2018-10-19 08:17:40 ERROR    Traceback (most recent call last):
  File "u:\Git Version Control\Air-Quality-Toolkit\PyQt\PyQt_AirQualityToolkit.py", line 507, in Stat_Browse_Clicked
    self.Stat_To_Convert.setText(filename[0])
IndexError: list index out of range
Traceback (most recent call last):
  File "u:\Git Version Control\Air-Quality-Toolkit\PyQt\PyQt_AirQualityToolkit.py", line 507, in Stat_Browse_Clicked
    self.Stat_To_Convert.setText(filename[0])
IndexError: list index out of range
2018-10-19 08:17:49 ERROR    Traceback (most recent call last):
  File "U:\Git Version Control\Air-Quality-Toolkit\Stitcher.py", line 68, in Stitcher
    dataout.to_csv(output_filename)
UnboundLocalError: local variable 'dataout' referenced before assignment
Traceback (most recent call last):
  File "U:\Git Version Control\Air-Quality-Toolkit\Stitcher.py", line 68, in Stitcher
    dataout.to_csv(output_filename)
UnboundLocalError: local variable 'dataout' referenced before assignment
2018-10-19 08:18:24 ERROR    Traceback (most recent call last):
  File "u:\Git Version Control\Air-Quality-Toolkit\PyQt\PyQt_AirQualityToolkit.py", line 507, in Stat_Browse_Clicked
    self.Stat_To_Convert.setText(filename[0])
IndexError: list index out of range
Traceback (most recent call last):
  File "u:\Git Version Control\Air-Quality-Toolkit\PyQt\PyQt_AirQualityToolkit.py", line 507, in Stat_Browse_Clicked
    self.Stat_To_Convert.setText(filename[0])
IndexError: list index out of range
2018-10-19 08:18:34 ERROR    Traceback (most recent call last):
  File "U:\Git Version Control\Air-Quality-Toolkit\Stitcher.py", line 68, in Stitcher
    dataout.to_csv(output_filename)
UnboundLocalError: local variable 'dataout' referenced before assignment
Traceback (most recent call last):
  File "U:\Git Version Control\Air-Quality-Toolkit\Stitcher.py", line 68, in Stitcher
    dataout.to_csv(output_filename)
UnboundLocalError: local variable 'dataout' referenced before assignment
2018-10-19 16:10:15 ERROR    Traceback (most recent call last):
  File "U:\Git Version Control\Air-Quality-Toolkit\CSVFormatter.py", line 41, in csvformatter
    for recepternum in range(1,int(line.split()[0])+1):
ValueError: invalid literal for int() with base 10: '1.1'
Traceback (most recent call last):
  File "U:\Git Version Control\Air-Quality-Toolkit\CSVFormatter.py", line 41, in csvformatter
    for recepternum in range(1,int(line.split()[0])+1):
ValueError: invalid literal for int() with base 10: '1.1'
2018-10-19 16:10:25 ERROR    Traceback (most recent call last):
  File "U:\Git Version Control\Air-Quality-Toolkit\CSVFormatter.py", line 41, in csvformatter
    for recepternum in range(1,int(line.split()[0])+1):
ValueError: invalid literal for int() with base 10: '1.1'
Traceback (most recent call last):
  File "U:\Git Version Control\Air-Quality-Toolkit\CSVFormatter.py", line 41, in csvformatter
    for recepternum in range(1,int(line.split()[0])+1):
ValueError: invalid literal for int() with base 10: '1.1'
2018-10-19 16:10:27 ERROR    Traceback (most recent call last):
  File "U:\Git Version Control\Air-Quality-Toolkit\CSVFormatter.py", line 41, in csvformatter
    for recepternum in range(1,int(line.split()[0])+1):
ValueError: invalid literal for int() with base 10: '1.1'
Traceback (most recent call last):
  File "U:\Git Version Control\Air-Quality-Toolkit\CSVFormatter.py", line 41, in csvformatter
    for recepternum in range(1,int(line.split()[0])+1):
ValueError: invalid literal for int() with base 10: '1.1'
2018-10-19 16:10:27 ERROR    Traceback (most recent call last):
  File "U:\Git Version Control\Air-Quality-Toolkit\CSVFormatter.py", line 41, in csvformatter
    for recepternum in range(1,int(line.split()[0])+1):
ValueError: invalid literal for int() with base 10: '1.1'
Traceback (most recent call last):
  File "U:\Git Version Control\Air-Quality-Toolkit\CSVFormatter.py", line 41, in csvformatter
    for recepternum in range(1,int(line.split()[0])+1):
ValueError: invalid literal for int() with base 10: '1.1'
2018-10-19 16:10:27 ERROR    Traceback (most recent call last):
  File "U:\Git Version Control\Air-Quality-Toolkit\CSVFormatter.py", line 41, in csvformatter
    for recepternum in range(1,int(line.split()[0])+1):
ValueError: invalid literal for int() with base 10: '1.1'
Traceback (most recent call last):
  File "U:\Git Version Control\Air-Quality-Toolkit\CSVFormatter.py", line 41, in csvformatter
    for recepternum in range(1,int(line.split()[0])+1):
ValueError: invalid literal for int() with base 10: '1.1'
2018-10-19 16:10:28 ERROR    Traceback (most recent call last):
  File "U:\Git Version Control\Air-Quality-Toolkit\CSVFormatter.py", line 41, in csvformatter
    for recepternum in range(1,int(line.split()[0])+1):
ValueError: invalid literal for int() with base 10: '1.1'
Traceback (most recent call last):
  File "U:\Git Version Control\Air-Quality-Toolkit\CSVFormatter.py", line 41, in csvformatter
    for recepternum in range(1,int(line.split()[0])+1):
ValueError: invalid literal for int() with base 10: '1.1'
2018-10-19 16:10:28 ERROR    Traceback (most recent call last):
  File "U:\Git Version Control\Air-Quality-Toolkit\CSVFormatter.py", line 41, in csvformatter
    for recepternum in range(1,int(line.split()[0])+1):
ValueError: invalid literal for int() with base 10: '1.1'
Traceback (most recent call last):
  File "U:\Git Version Control\Air-Quality-Toolkit\CSVFormatter.py", line 41, in csvformatter
    for recepternum in range(1,int(line.split()[0])+1):
ValueError: invalid literal for int() with base 10: '1.1'
2018-10-19 16:10:28 ERROR    Traceback (most recent call last):
  File "U:\Git Version Control\Air-Quality-Toolkit\CSVFormatter.py", line 41, in csvformatter
    for recepternum in range(1,int(line.split()[0])+1):
ValueError: invalid literal for int() with base 10: '1.1'
Traceback (most recent call last):
  File "U:\Git Version Control\Air-Quality-Toolkit\CSVFormatter.py", line 41, in csvformatter
    for recepternum in range(1,int(line.split()[0])+1):
ValueError: invalid literal for int() with base 10: '1.1'
2018-10-19 16:11:54 ERROR    Traceback (most recent call last):
  File "U:\Git Version Control\Air-Quality-Toolkit\CSVFormatter.py", line 41, in csvformatter
    for recepternum in range(1,int(line.split(":")[-1])+1):
ValueError: invalid literal for int() with base 10: '00\t0\t0\t0\t0\t0\t0\t0\t0\t0\t0\t0\t0\t0\t0\t0\t0\t0\t0\t0\t0\t0\t0\t0\t0\t0\t0\t0\t0\t0\t0\t0\t0\t0\t0\t0\t0\t0\t0\t0\t0\t0\t0\t0\t0\t0\t0\t0\t0\t0\t0\t0\t0\t0\t0\t0\t0\t0\t0\t0\t0\t0\t0\t0\t0\t0\t
Traceback (most recent call last):
  File "U:\Git Version Control\Air-Quality-Toolkit\CSVFormatter.py", line 41, in csvformatter
    for recepternum in range(1,int(line.split(":")[-1])+1):
ValueError: invalid literal for int() with base 10: '00\t0\t0\t0\t0\t0\t0\t0\t0\t0\t0\t0\t0\t0\t0\t0\t0\t0\t0\t0\t0\t0\t0\t0\t0\t0\t0\t0\t0\t0\t0\t0\t0\t0\t0\t0\t0\t0\t0\t0\t0\t0\t0\t0\t0\t0\t0\t0\t0\t0\t0\t0\t0\t0\t0\t0\t0\t0\t0\t0\t0\t0\t0\t0\t0\t0\t
2018-10-19 16:11:57 ERROR    Traceback (most recent call last):
  File "U:\Git Version Control\Air-Quality-Toolkit\CSVFormatter.py", line 41, in csvformatter
    for recepternum in range(1,int(line.split(":")[-1])+1):
ValueError: invalid literal for int() with base 10: '00\t0\t0\t0\t0\t0\t0\t0\t0\t0\t0\t0\t0\t0\t0\t0\t0\t0\t0\t0\t0\t0\t0\t0\t0\t0\t0\t0\t0\t0\t0\t0\t0\t0\t0\t0\t0\t0\t0\t0\t0\t0\t0\t0\t0\t0\t0\t0\t0\t0\t0\t0\t0\t0\t0\t0\t0\t0\t0\t0\t0\t0\t0\t0\t0\t0\t
Traceback (most recent call last):
  File "U:\Git Version Control\Air-Quality-Toolkit\CSVFormatter.py", line 41, in csvformatter
    for recepternum in range(1,int(line.split(":")[-1])+1):
ValueError: invalid literal for int() with base 10: '00\t0\t0\t0\t0\t0\t0\t0\t0\t0\t0\t0\t0\t0\t0\t0\t0\t0\t0\t0\t0\t0\t0\t0\t0\t0\t0\t0\t0\t0\t0\t0\t0\t0\t0\t0\t0\t0\t0\t0\t0\t0\t0\t0\t0\t0\t0\t0\t0\t0\t0\t0\t0\t0\t0\t0\t0\t0\t0\t0\t0\t0\t0\t0\t0\t0\t
2018-10-19 16:11:58 ERROR    Traceback (most recent call last):
  File "U:\Git Version Control\Air-Quality-Toolkit\CSVFormatter.py", line 41, in csvformatter
    for recepternum in range(1,int(line.split(":")[-1])+1):
ValueError: invalid literal for int() with base 10: '00\t8.68872066251043\t7.45566426149263\t3.43260513546913\t3.15584048895156\t2.86340274149151\t2.40001154268483\t3.53759076736452\t4.32015773536855\t2.53038275005405\t1.40493979367578\t1.9710262744931
Traceback (most recent call last):
  File "U:\Git Version Control\Air-Quality-Toolkit\CSVFormatter.py", line 41, in csvformatter
    for recepternum in range(1,int(line.split(":")[-1])+1):
ValueError: invalid literal for int() with base 10: '00\t8.68872066251043\t7.45566426149263\t3.43260513546913\t3.15584048895156\t2.86340274149151\t2.40001154268483\t3.53759076736452\t4.32015773536855\t2.53038275005405\t1.40493979367578\t1.9710262744931
2018-10-19 16:11:58 ERROR    Traceback (most recent call last):
  File "U:\Git Version Control\Air-Quality-Toolkit\CSVFormatter.py", line 41, in csvformatter
    for recepternum in range(1,int(line.split(":")[-1])+1):
ValueError: invalid literal for int() with base 10: '00\t36.686007837295\t23.5985354085081\t10.6721235693146\t8.92770953178202\t7.25258805714748\t6.6939172794571\t12.1598273785318\t12.7751405419831\t6.96130712540032\t5.15663158967925\t4.45332013127695\
Traceback (most recent call last):
  File "U:\Git Version Control\Air-Quality-Toolkit\CSVFormatter.py", line 41, in csvformatter
    for recepternum in range(1,int(line.split(":")[-1])+1):
ValueError: invalid literal for int() with base 10: '00\t36.686007837295\t23.5985354085081\t10.6721235693146\t8.92770953178202\t7.25258805714748\t6.6939172794571\t12.1598273785318\t12.7751405419831\t6.96130712540032\t5.15663158967925\t4.45332013127695\
2018-10-19 16:11:58 ERROR    Traceback (most recent call last):
  File "U:\Git Version Control\Air-Quality-Toolkit\CSVFormatter.py", line 41, in csvformatter
    for recepternum in range(1,int(line.split(":")[-1])+1):
ValueError: invalid literal for int() with base 10: '00\t35.6053632886692\t23.53768740535\t10.2036684910323\t8.82346906768722\t7.06177273938572\t6.04194433486663\t10.7184304097158\t12.1330307023425\t5.8315200959041\t3.47862386719503\t4.22132336195378\t
Traceback (most recent call last):
  File "U:\Git Version Control\Air-Quality-Toolkit\CSVFormatter.py", line 41, in csvformatter
    for recepternum in range(1,int(line.split(":")[-1])+1):
ValueError: invalid literal for int() with base 10: '00\t35.6053632886692\t23.53768740535\t10.2036684910323\t8.82346906768722\t7.06177273938572\t6.04194433486663\t10.7184304097158\t12.1330307023425\t5.8315200959041\t3.47862386719503\t4.22132336195378\t
2018-10-19 16:11:59 ERROR    Traceback (most recent call last):
  File "U:\Git Version Control\Air-Quality-Toolkit\CSVFormatter.py", line 41, in csvformatter
    for recepternum in range(1,int(line.split(":")[-1])+1):
ValueError: invalid literal for int() with base 10: '00\t32.0463257589282\t21.4730147763465\t10.8574121633492\t9.30747970285209\t8.08884365146408\t6.8167499439302\t11.4040634003793\t12.8875160115082\t7.17987285225836\t4.2551957204524\t4.86569750607804\
Traceback (most recent call last):
  File "U:\Git Version Control\Air-Quality-Toolkit\CSVFormatter.py", line 41, in csvformatter
    for recepternum in range(1,int(line.split(":")[-1])+1):
ValueError: invalid literal for int() with base 10: '00\t32.0463257589282\t21.4730147763465\t10.8574121633492\t9.30747970285209\t8.08884365146408\t6.8167499439302\t11.4040634003793\t12.8875160115082\t7.17987285225836\t4.2551957204524\t4.86569750607804\
2018-10-19 16:11:59 ERROR    Traceback (most recent call last):
  File "U:\Git Version Control\Air-Quality-Toolkit\CSVFormatter.py", line 41, in csvformatter
    for recepternum in range(1,int(line.split(":")[-1])+1):
ValueError: invalid literal for int() with base 10: '00\t0.0733967033433326\t0.0488946786142671\t0\t0.0674954295894246\t0.0209613788275071\t0.0234301970819387\t0.0474155599197733\t0.091762824804204\t0\t0\t0.0397490608839341\t0.025117724765966\t0\t0\t0.
Traceback (most recent call last):
  File "U:\Git Version Control\Air-Quality-Toolkit\CSVFormatter.py", line 41, in csvformatter
    for recepternum in range(1,int(line.split(":")[-1])+1):
ValueError: invalid literal for int() with base 10: '00\t0.0733967033433326\t0.0488946786142671\t0\t0.0674954295894246\t0.0209613788275071\t0.0234301970819387\t0.0474155599197733\t0.091762824804204\t0\t0\t0.0397490608839341\t0.025117724765966\t0\t0\t0.
2018-10-19 16:11:59 ERROR    Traceback (most recent call last):
  File "U:\Git Version Control\Air-Quality-Toolkit\CSVFormatter.py", line 41, in csvformatter
    for recepternum in range(1,int(line.split(":")[-1])+1):
ValueError: invalid literal for int() with base 10: '00\t30.6672620601615\t23.8571916226252\t18.9722908895325\t15.372605389099\t13.6274422236063\t12.5815695573273\t15.4803701913283\t17.2639994013579\t11.2847410810828\t8.19273996316356\t8.36061572372422
Traceback (most recent call last):
  File "U:\Git Version Control\Air-Quality-Toolkit\CSVFormatter.py", line 41, in csvformatter
    for recepternum in range(1,int(line.split(":")[-1])+1):
ValueError: invalid literal for int() with base 10: '00\t30.6672620601615\t23.8571916226252\t18.9722908895325\t15.372605389099\t13.6274422236063\t12.5815695573273\t15.4803701913283\t17.2639994013579\t11.2847410810828\t8.19273996316356\t8.36061572372422
2018-10-25 09:19:23 ERROR    Traceback (most recent call last):
  File "U:\Git Version Control\Air-Quality-Toolkit\CSVFormatter.py", line 54, in csvformatter
    in_txt = csv.reader(open(txt_file, "r"), delimiter = '\t')
FileNotFoundError: [Errno 2] No such file or directory: 'Receptor_timeseries_BlockB_Stack1-2_NOx.txt'
Traceback (most recent call last):
  File "U:\Git Version Control\Air-Quality-Toolkit\CSVFormatter.py", line 54, in csvformatter
    in_txt = csv.reader(open(txt_file, "r"), delimiter = '\t')
FileNotFoundError: [Errno 2] No such file or directory: 'Receptor_timeseries_BlockB_Stack1-2_NOx.txt'
2018-10-25 09:19:25 ERROR    Traceback (most recent call last):
  File "U:\Git Version Control\Air-Quality-Toolkit\CSVFormatter.py", line 54, in csvformatter
    in_txt = csv.reader(open(txt_file, "r"), delimiter = '\t')
FileNotFoundError: [Errno 2] No such file or directory: 'Receptor_timeseries_BlockB_Stack1-2_NOx - Copy.txt'
Traceback (most recent call last):
  File "U:\Git Version Control\Air-Quality-Toolkit\CSVFormatter.py", line 54, in csvformatter
    in_txt = csv.reader(open(txt_file, "r"), delimiter = '\t')
FileNotFoundError: [Errno 2] No such file or directory: 'Receptor_timeseries_BlockB_Stack1-2_NOx - Copy.txt'
2018-10-25 09:19:29 ERROR    Traceback (most recent call last):
  File "U:\Git Version Control\Air-Quality-Toolkit\CSVFormatter.py", line 54, in csvformatter
    in_txt = csv.reader(open(txt_file, "r"), delimiter = '\t')
FileNotFoundError: [Errno 2] No such file or directory: 'Receptor_timeseries_BlockB_Stack1-2_NOx - Copy (2).txt'
Traceback (most recent call last):
  File "U:\Git Version Control\Air-Quality-Toolkit\CSVFormatter.py", line 54, in csvformatter
    in_txt = csv.reader(open(txt_file, "r"), delimiter = '\t')
FileNotFoundError: [Errno 2] No such file or directory: 'Receptor_timeseries_BlockB_Stack1-2_NOx - Copy (2).txt'
2018-10-25 09:26:24 ERROR    list index out of range
Traceback (most recent call last):
  File "u:\Git Version Control\Air-Quality-Toolkit\PyQt\PyQt_AirQualityToolkit.py", line 598, in Stitcher_Run_Clicked
    scalesl.append(row[2])
IndexError: list index out of range
2018-10-25 09:26:27 ERROR    Traceback (most recent call last):
  File "U:\Git Version Control\Air-Quality-Toolkit\Stitcher.py", line 68, in Stitcher
    dataout.to_csv(output_filename)
UnboundLocalError: local variable 'dataout' referenced before assignment
Traceback (most recent call last):
  File "U:\Git Version Control\Air-Quality-Toolkit\Stitcher.py", line 68, in Stitcher
    dataout.to_csv(output_filename)
UnboundLocalError: local variable 'dataout' referenced before assignment
2018-10-25 09:31:30 ERROR    Traceback (most recent call last):
  File "U:\Git Version Control\Air-Quality-Toolkit\Stitcher.py", line 69, in Stitcher
    dataout.to_csv(output_filename)
AttributeError: 'NoneType' object has no attribute 'to_csv'
Traceback (most recent call last):
  File "U:\Git Version Control\Air-Quality-Toolkit\Stitcher.py", line 69, in Stitcher
    dataout.to_csv(output_filename)
AttributeError: 'NoneType' object has no attribute 'to_csv'
2018-10-25 09:32:01 ERROR    Traceback (most recent call last):
  File "U:\Git Version Control\Air-Quality-Toolkit\Stitcher.py", line 69, in Stitcher
    dataout.to_csv(output_filename)
AttributeError: 'NoneType' object has no attribute 'to_csv'
Traceback (most recent call last):
  File "U:\Git Version Control\Air-Quality-Toolkit\Stitcher.py", line 69, in Stitcher
    dataout.to_csv(output_filename)
AttributeError: 'NoneType' object has no attribute 'to_csv'
2018-10-25 09:36:11 ERROR    Traceback (most recent call last):
  File "U:\Git Version Control\Air-Quality-Toolkit\Stitcher.py", line 62, in Stitcher
    if(dataout.shape != data.shape()):
TypeError: 'tuple' object is not callable
Traceback (most recent call last):
  File "U:\Git Version Control\Air-Quality-Toolkit\Stitcher.py", line 62, in Stitcher
    if(dataout.shape != data.shape()):
TypeError: 'tuple' object is not callable
2018-10-25 09:36:49 ERROR    Traceback (most recent call last):
  File "U:\Git Version Control\Air-Quality-Toolkit\Stitcher.py", line 63, in Stitcher
    ErrorBox("Datasets Size Error","Please review data sets size (eg missing hour or day)",err)
UnboundLocalError: local variable 'err' referenced before assignment
Traceback (most recent call last):
  File "U:\Git Version Control\Air-Quality-Toolkit\Stitcher.py", line 63, in Stitcher
    ErrorBox("Datasets Size Error","Please review data sets size (eg missing hour or day)",err)
UnboundLocalError: local variable 'err' referenced before assignment
2018-10-25 09:38:08 ERROR    
NoneType: None
2018-10-25 09:40:08 ERROR    
NoneType: None
2018-10-25 09:41:33 ERROR    Expecting data set size of (8759, 125) 
 Received: (365, 3291)
NoneType: None
2018-10-25 09:59:26 ERROR    Expecting data set size of (8759, 125) 
 Received: (3287, 10)
NoneType: None
2018-10-26 08:46:32 ERROR    Traceback (most recent call last):
  File "u:\Git Version Control\Air-Quality-Toolkit\PyQt\PyQt_AirQualityToolkit.py", line 698, in MassCSV_Browse_Clicked
    self.MassCSV_Table.setItem(row,2,QTableWidgetItem(filename.split('.')[0] + "_Formatted.csv"))
AttributeError: 'list' object has no attribute 'split'
Traceback (most recent call last):
  File "u:\Git Version Control\Air-Quality-Toolkit\PyQt\PyQt_AirQualityToolkit.py", line 698, in MassCSV_Browse_Clicked
    self.MassCSV_Table.setItem(row,2,QTableWidgetItem(filename.split('.')[0] + "_Formatted.csv"))
AttributeError: 'list' object has no attribute 'split'
2018-10-26 08:47:12 ERROR    Traceback (most recent call last):
  File "C:\Users\McKewJ\Anaconda\envs\AirQualityToolkit\lib\site-packages\pandas\core\indexing.py", line 1790, in _validate_key
    error()
  File "C:\Users\McKewJ\Anaconda\envs\AirQualityToolkit\lib\site-packages\pandas\core\indexing.py", line 1785, in error
    axis=self.obj._get_axis_name(axis)))
KeyError: 'the label [Filename] is not in the [columns]'

During handling of the above exception, another exception occurred:

Traceback (most recent call last):
  File "u:\Git Version Control\Air-Quality-Toolkit\PyQt\PyQt_AirQualityToolkit.py", line 714, in MassCSV_Import_Clicked
    for filename,calpuff,row in zip(settings.loc[:,'Filename'],settings.loc[:,'XY Included'],range(len(settings.loc[:,'Filename']))):
  File "C:\Users\McKewJ\Anaconda\envs\AirQualityToolkit\lib\site-packages\pandas\core\indexing.py", line 1472, in __getitem__
    return self._getitem_tuple(key)
  File "C:\Users\McKewJ\Anaconda\envs\AirQualityToolkit\lib\site-packages\pandas\core\indexing.py", line 870, in _getitem_tuple
    return self._getitem_lowerdim(tup)
  File "C:\Users\McKewJ\Anaconda\envs\AirQualityToolkit\lib\site-packages\pandas\core\indexing.py", line 998, in _getitem_lowerdim
    section = self._getitem_axis(key, axis=i)
  File "C:\Users\McKewJ\Anaconda\envs\AirQualityToolkit\lib\site-packages\pandas\core\indexing.py", line 1911, in _getitem_axis
    self._validate_key(key, axis)
  File "C:\Users\McKewJ\Anaconda\envs\AirQualityToolkit\lib\site-packages\pandas\core\indexing.py", line 1798, in _validate_key
    error()
  File "C:\Users\McKewJ\Anaconda\envs\AirQualityToolkit\lib\site-packages\pandas\core\indexing.py", line 1785, in error
    axis=self.obj._get_axis_name(axis)))
KeyError: 'the label [Filename] is not in the [columns]'
Traceback (most recent call last):
  File "C:\Users\McKewJ\Anaconda\envs\AirQualityToolkit\lib\site-packages\pandas\core\indexing.py", line 1790, in _validate_key
    error()
  File "C:\Users\McKewJ\Anaconda\envs\AirQualityToolkit\lib\site-packages\pandas\core\indexing.py", line 1785, in error
    axis=self.obj._get_axis_name(axis)))
KeyError: 'the label [Filename] is not in the [columns]'

During handling of the above exception, another exception occurred:

Traceback (most recent call last):
  File "u:\Git Version Control\Air-Quality-Toolkit\PyQt\PyQt_AirQualityToolkit.py", line 714, in MassCSV_Import_Clicked
    for filename,calpuff,row in zip(settings.loc[:,'Filename'],settings.loc[:,'XY Included'],range(len(settings.loc[:,'Filename']))):
  File "C:\Users\McKewJ\Anaconda\envs\AirQualityToolkit\lib\site-packages\pandas\core\indexing.py", line 1472, in __getitem__
    return self._getitem_tuple(key)
  File "C:\Users\McKewJ\Anaconda\envs\AirQualityToolkit\lib\site-packages\pandas\core\indexing.py", line 870, in _getitem_tuple
    return self._getitem_lowerdim(tup)
  File "C:\Users\McKewJ\Anaconda\envs\AirQualityToolkit\lib\site-packages\pandas\core\indexing.py", line 998, in _getitem_lowerdim
    section = self._getitem_axis(key, axis=i)
  File "C:\Users\McKewJ\Anaconda\envs\AirQualityToolkit\lib\site-packages\pandas\core\indexing.py", line 1911, in _getitem_axis
    self._validate_key(key, axis)
  File "C:\Users\McKewJ\Anaconda\envs\AirQualityToolkit\lib\site-packages\pandas\core\indexing.py", line 1798, in _validate_key
    error()
  File "C:\Users\McKewJ\Anaconda\envs\AirQualityToolkit\lib\site-packages\pandas\core\indexing.py", line 1785, in error
    axis=self.obj._get_axis_name(axis)))
KeyError: 'the label [Filename] is not in the [columns]'
2018-10-26 08:49:25 ERROR    Traceback (most recent call last):
  File "U:\Git Version Control\Air-Quality-Toolkit\CSVFormatter.py", line 58, in csvformatter
    in_txt = csv.read(open(txt_file,"r"))
AttributeError: module 'csv' has no attribute 'read'
Traceback (most recent call last):
  File "U:\Git Version Control\Air-Quality-Toolkit\CSVFormatter.py", line 58, in csvformatter
    in_txt = csv.read(open(txt_file,"r"))
AttributeError: module 'csv' has no attribute 'read'
2018-10-26 08:49:27 ERROR    Traceback (most recent call last):
  File "U:\Git Version Control\Air-Quality-Toolkit\CSVFormatter.py", line 58, in csvformatter
    in_txt = csv.read(open(txt_file,"r"))
AttributeError: module 'csv' has no attribute 'read'
Traceback (most recent call last):
  File "U:\Git Version Control\Air-Quality-Toolkit\CSVFormatter.py", line 58, in csvformatter
    in_txt = csv.read(open(txt_file,"r"))
AttributeError: module 'csv' has no attribute 'read'
2018-10-26 08:54:22 ERROR    Traceback (most recent call last):
  File "U:\Git Version Control\Air-Quality-Toolkit\CSVFormatter.py", line 59, in csvformatter
    delimter = sniffer.sniff(in_txt)
  File "C:\Users\McKewJ\Anaconda\envs\AirQualityToolkit\lib\csv.py", line 182, in sniff
    self._guess_quote_and_delimiter(sample, delimiters)
  File "C:\Users\McKewJ\Anaconda\envs\AirQualityToolkit\lib\csv.py", line 223, in _guess_quote_and_delimiter
    matches = regexp.findall(data)
TypeError: expected string or bytes-like object
Traceback (most recent call last):
  File "U:\Git Version Control\Air-Quality-Toolkit\CSVFormatter.py", line 59, in csvformatter
    delimter = sniffer.sniff(in_txt)
  File "C:\Users\McKewJ\Anaconda\envs\AirQualityToolkit\lib\csv.py", line 182, in sniff
    self._guess_quote_and_delimiter(sample, delimiters)
  File "C:\Users\McKewJ\Anaconda\envs\AirQualityToolkit\lib\csv.py", line 223, in _guess_quote_and_delimiter
    matches = regexp.findall(data)
TypeError: expected string or bytes-like object
2018-10-26 08:54:29 ERROR    Traceback (most recent call last):
  File "U:\Git Version Control\Air-Quality-Toolkit\CSVFormatter.py", line 59, in csvformatter
    delimter = sniffer.sniff(in_txt)
  File "C:\Users\McKewJ\Anaconda\envs\AirQualityToolkit\lib\csv.py", line 182, in sniff
    self._guess_quote_and_delimiter(sample, delimiters)
  File "C:\Users\McKewJ\Anaconda\envs\AirQualityToolkit\lib\csv.py", line 223, in _guess_quote_and_delimiter
    matches = regexp.findall(data)
TypeError: expected string or bytes-like object
Traceback (most recent call last):
  File "U:\Git Version Control\Air-Quality-Toolkit\CSVFormatter.py", line 59, in csvformatter
    delimter = sniffer.sniff(in_txt)
  File "C:\Users\McKewJ\Anaconda\envs\AirQualityToolkit\lib\csv.py", line 182, in sniff
    self._guess_quote_and_delimiter(sample, delimiters)
  File "C:\Users\McKewJ\Anaconda\envs\AirQualityToolkit\lib\csv.py", line 223, in _guess_quote_and_delimiter
    matches = regexp.findall(data)
TypeError: expected string or bytes-like object
2018-10-26 08:55:24 ERROR    Traceback (most recent call last):
  File "u:\Git Version Control\Air-Quality-Toolkit\PyQt\PyQt_AirQualityToolkit.py", line 697, in MassCSV_Browse_Clicked
    self.MassCSV_Table.setItem(row,0,QTableWidgetItem(filename[0]))
IndexError: list index out of range
Traceback (most recent call last):
  File "u:\Git Version Control\Air-Quality-Toolkit\PyQt\PyQt_AirQualityToolkit.py", line 697, in MassCSV_Browse_Clicked
    self.MassCSV_Table.setItem(row,0,QTableWidgetItem(filename[0]))
IndexError: list index out of range
2018-10-26 08:55:48 ERROR    Traceback (most recent call last):
  File "U:\Git Version Control\Air-Quality-Toolkit\CSVFormatter.py", line 62, in csvformatter
    in_txt = csv.reader(open(txt_file,"r"),delimiter=delimter)
TypeError: "delimiter" must be string, not type
Traceback (most recent call last):
  File "U:\Git Version Control\Air-Quality-Toolkit\CSVFormatter.py", line 62, in csvformatter
    in_txt = csv.reader(open(txt_file,"r"),delimiter=delimter)
TypeError: "delimiter" must be string, not type
2018-10-26 09:14:05 ERROR    Traceback (most recent call last):
  File "U:\Git Version Control\Air-Quality-Toolkit\CSVFormatter.py", line 62, in csvformatter
    test_csv = csv.reader(open(out_csv),"r")
TypeError: expected str, bytes or os.PathLike object, not _csv.writer
Traceback (most recent call last):
  File "U:\Git Version Control\Air-Quality-Toolkit\CSVFormatter.py", line 62, in csvformatter
    test_csv = csv.reader(open(out_csv),"r")
TypeError: expected str, bytes or os.PathLike object, not _csv.writer
2018-10-26 09:14:46 ERROR    Traceback (most recent call last):
  File "U:\Git Version Control\Air-Quality-Toolkit\CSVFormatter.py", line 62, in csvformatter
    test_csv = csv.reader(open(outpath),"r")
_csv.Error: unknown dialect
Traceback (most recent call last):
  File "U:\Git Version Control\Air-Quality-Toolkit\CSVFormatter.py", line 62, in csvformatter
    test_csv = csv.reader(open(outpath),"r")
_csv.Error: unknown dialect
2018-10-26 09:18:35 ERROR    Traceback (most recent call last):
  File "U:\Git Version Control\Air-Quality-Toolkit\CSVFormatter.py", line 58, in csvformatter
    if(delimquestion == QMessageBox.Yes):
UnboundLocalError: local variable 'delimquestion' referenced before assignment
Traceback (most recent call last):
  File "U:\Git Version Control\Air-Quality-Toolkit\CSVFormatter.py", line 58, in csvformatter
    if(delimquestion == QMessageBox.Yes):
UnboundLocalError: local variable 'delimquestion' referenced before assignment
2018-10-26 09:28:12 ERROR    Traceback (most recent call last):
  File "U:\Git Version Control\Air-Quality-Toolkit\CSVFormatter.py", line 62, in csvformatter
    out_csv = csv.writer(open(outpath, 'w',newline=''))
PermissionError: [Errno 13] Permission denied: 'U:/Git Version Control/Test Datasets/TSERIES_MEBR_24HR_CONC_C_Formatted.csv'
Traceback (most recent call last):
  File "U:\Git Version Control\Air-Quality-Toolkit\CSVFormatter.py", line 62, in csvformatter
    out_csv = csv.writer(open(outpath, 'w',newline=''))
PermissionError: [Errno 13] Permission denied: 'U:/Git Version Control/Test Datasets/TSERIES_MEBR_24HR_CONC_C_Formatted.csv'
2018-11-08 15:24:37 ERROR    Traceback (most recent call last):
  File "u:\Git Version Control\Air-Quality-Toolkit\PyQt\PyQt_AirQualityToolkit.py", line 562, in Stat_Browse_Clicked
    self.Stat_To_Convert.setText(filename[0])
IndexError: list index out of range
Traceback (most recent call last):
  File "u:\Git Version Control\Air-Quality-Toolkit\PyQt\PyQt_AirQualityToolkit.py", line 562, in Stat_Browse_Clicked
    self.Stat_To_Convert.setText(filename[0])
IndexError: list index out of range
2018-11-09 11:36:05 ERROR    Traceback (most recent call last):
  File "u:\Git Version Control\Air-Quality-Toolkit\PyQt\PyQt_AirQualityToolkit.py", line 602, in Stat_Con_In_Clicked
    self.Stat_Con_Input_Name.setText(filename[0])
IndexError: list index out of range
Traceback (most recent call last):
  File "u:\Git Version Control\Air-Quality-Toolkit\PyQt\PyQt_AirQualityToolkit.py", line 602, in Stat_Con_In_Clicked
    self.Stat_Con_Input_Name.setText(filename[0])
IndexError: list index out of range
2018-11-09 12:47:50 ERROR    Traceback (most recent call last):
  File "u:\Git Version Control\Air-Quality-Toolkit\PyQt\PyQt_AirQualityToolkit.py", line 617, in Stat_Con_Back_Clicked
    self.Stat_Con_Back_Name.setText(filename[0])
IndexError: list index out of range
Traceback (most recent call last):
  File "u:\Git Version Control\Air-Quality-Toolkit\PyQt\PyQt_AirQualityToolkit.py", line 617, in Stat_Con_Back_Clicked
    self.Stat_Con_Back_Name.setText(filename[0])
IndexError: list index out of range
2018-11-30 09:32:48 ERROR    Traceback (most recent call last):
  File "u:\Git Version Control\Air-Quality-Toolkit\PyQt\PyQt_AirQualityToolkit.py", line 604, in Stat_Con_In_Clicked
    self.Stat_Con_Input_Name.setText(filename[0])
IndexError: list index out of range
Traceback (most recent call last):
  File "u:\Git Version Control\Air-Quality-Toolkit\PyQt\PyQt_AirQualityToolkit.py", line 604, in Stat_Con_In_Clicked
    self.Stat_Con_Input_Name.setText(filename[0])
IndexError: list index out of range
2018-11-30 09:36:39 ERROR    Traceback (most recent call last):
  File "u:\Git Version Control\Air-Quality-Toolkit\PyQt_AirQualityToolkit.py", line 618, in Stat_Con_Back_Clicked
    self.Stat_Con_Back_Name.setText(filename[0])
IndexError: list index out of range
Traceback (most recent call last):
  File "u:\Git Version Control\Air-Quality-Toolkit\PyQt_AirQualityToolkit.py", line 618, in Stat_Con_Back_Clicked
    self.Stat_Con_Back_Name.setText(filename[0])
IndexError: list index out of range
2018-11-30 09:36:39 ERROR    Traceback (most recent call last):
  File "u:\Git Version Control\Air-Quality-Toolkit\PyQt_AirQualityToolkit.py", line 618, in Stat_Con_Back_Clicked
    self.Stat_Con_Back_Name.setText(filename[0])
IndexError: list index out of range
Traceback (most recent call last):
  File "u:\Git Version Control\Air-Quality-Toolkit\PyQt_AirQualityToolkit.py", line 618, in Stat_Con_Back_Clicked
    self.Stat_Con_Back_Name.setText(filename[0])
IndexError: list index out of range
2018-11-30 10:18:13 ERROR    Traceback (most recent call last):
  File "C:\Users\McKewJ\Anaconda\envs\AirQualityToolkit\lib\site-packages\pandas\core\indexes\base.py", line 3078, in get_loc
    return self._engine.get_loc(key)
  File "pandas/_libs/index.pyx", line 140, in pandas._libs.index.IndexEngine.get_loc
  File "pandas/_libs/index.pyx", line 162, in pandas._libs.index.IndexEngine.get_loc
  File "pandas/_libs/hashtable_class_helper.pxi", line 1492, in pandas._libs.hashtable.PyObjectHashTable.get_item
  File "pandas/_libs/hashtable_class_helper.pxi", line 1500, in pandas._libs.hashtable.PyObjectHashTable.get_item
KeyError: 'background'

During handling of the above exception, another exception occurred:

Traceback (most recent call last):
  File "C:\Users\McKewJ\Anaconda\envs\AirQualityToolkit\lib\site-packages\pandas\core\internals.py", line 4243, in set
    loc = self.items.get_loc(item)
  File "C:\Users\McKewJ\Anaconda\envs\AirQualityToolkit\lib\site-packages\pandas\core\indexes\base.py", line 3080, in get_loc
    return self._engine.get_loc(self._maybe_cast_indexer(key))
  File "pandas/_libs/index.pyx", line 140, in pandas._libs.index.IndexEngine.get_loc
  File "pandas/_libs/index.pyx", line 162, in pandas._libs.index.IndexEngine.get_loc
  File "pandas/_libs/hashtable_class_helper.pxi", line 1492, in pandas._libs.hashtable.PyObjectHashTable.get_item
  File "pandas/_libs/hashtable_class_helper.pxi", line 1500, in pandas._libs.hashtable.PyObjectHashTable.get_item
KeyError: 'background'

During handling of the above exception, another exception occurred:

Traceback (most recent call last):
  File "u:\Git Version Control\Air-Quality-Toolkit\modules\Contemporaneous.py", line 43, in contemporaneous
    data['background'] = background.iloc[:,header_length:]
  File "C:\Users\McKewJ\Anaconda\envs\AirQualityToolkit\lib\site-packages\pandas\core\frame.py", line 3119, in __setitem__
    self._set_item(key, value)
  File "C:\Users\McKewJ\Anaconda\envs\AirQualityToolkit\lib\site-packages\pandas\core\frame.py", line 3195, in _set_item
    NDFrame._set_item(self, key, value)
  File "C:\Users\McKewJ\Anaconda\envs\AirQualityToolkit\lib\site-packages\pandas\core\generic.py", line 2600, in _set_item
    self._data.set(key, value)
  File "C:\Users\McKewJ\Anaconda\envs\AirQualityToolkit\lib\site-packages\pandas\core\internals.py", line 4246, in set
    self.insert(len(self.items), item, value)
  File "C:\Users\McKewJ\Anaconda\envs\AirQualityToolkit\lib\site-packages\pandas\core\internals.py", line 4347, in insert
    placement=slice(loc, loc + 1))
  File "C:\Users\McKewJ\Anaconda\envs\AirQualityToolkit\lib\site-packages\pandas\core\internals.py", line 3205, in make_block
    return klass(values, ndim=ndim, placement=placement)
  File "C:\Users\McKewJ\Anaconda\envs\AirQualityToolkit\lib\site-packages\pandas\core\internals.py", line 125, in __init__
    '{mgr}'.format(val=len(self.values), mgr=len(self.mgr_locs)))
ValueError: Wrong number of items passed 2, placement implies 1
Traceback (most recent call last):
  File "C:\Users\McKewJ\Anaconda\envs\AirQualityToolkit\lib\site-packages\pandas\core\indexes\base.py", line 3078, in get_loc
    return self._engine.get_loc(key)
  File "pandas/_libs/index.pyx", line 140, in pandas._libs.index.IndexEngine.get_loc
  File "pandas/_libs/index.pyx", line 162, in pandas._libs.index.IndexEngine.get_loc
  File "pandas/_libs/hashtable_class_helper.pxi", line 1492, in pandas._libs.hashtable.PyObjectHashTable.get_item
  File "pandas/_libs/hashtable_class_helper.pxi", line 1500, in pandas._libs.hashtable.PyObjectHashTable.get_item
KeyError: 'background'

During handling of the above exception, another exception occurred:

Traceback (most recent call last):
  File "C:\Users\McKewJ\Anaconda\envs\AirQualityToolkit\lib\site-packages\pandas\core\internals.py", line 4243, in set
    loc = self.items.get_loc(item)
  File "C:\Users\McKewJ\Anaconda\envs\AirQualityToolkit\lib\site-packages\pandas\core\indexes\base.py", line 3080, in get_loc
    return self._engine.get_loc(self._maybe_cast_indexer(key))
  File "pandas/_libs/index.pyx", line 140, in pandas._libs.index.IndexEngine.get_loc
  File "pandas/_libs/index.pyx", line 162, in pandas._libs.index.IndexEngine.get_loc
  File "pandas/_libs/hashtable_class_helper.pxi", line 1492, in pandas._libs.hashtable.PyObjectHashTable.get_item
  File "pandas/_libs/hashtable_class_helper.pxi", line 1500, in pandas._libs.hashtable.PyObjectHashTable.get_item
KeyError: 'background'

During handling of the above exception, another exception occurred:

Traceback (most recent call last):
  File "u:\Git Version Control\Air-Quality-Toolkit\modules\Contemporaneous.py", line 43, in contemporaneous
    data['background'] = background.iloc[:,header_length:]
  File "C:\Users\McKewJ\Anaconda\envs\AirQualityToolkit\lib\site-packages\pandas\core\frame.py", line 3119, in __setitem__
    self._set_item(key, value)
  File "C:\Users\McKewJ\Anaconda\envs\AirQualityToolkit\lib\site-packages\pandas\core\frame.py", line 3195, in _set_item
    NDFrame._set_item(self, key, value)
  File "C:\Users\McKewJ\Anaconda\envs\AirQualityToolkit\lib\site-packages\pandas\core\generic.py", line 2600, in _set_item
    self._data.set(key, value)
  File "C:\Users\McKewJ\Anaconda\envs\AirQualityToolkit\lib\site-packages\pandas\core\internals.py", line 4246, in set
    self.insert(len(self.items), item, value)
  File "C:\Users\McKewJ\Anaconda\envs\AirQualityToolkit\lib\site-packages\pandas\core\internals.py", line 4347, in insert
    placement=slice(loc, loc + 1))
  File "C:\Users\McKewJ\Anaconda\envs\AirQualityToolkit\lib\site-packages\pandas\core\internals.py", line 3205, in make_block
    return klass(values, ndim=ndim, placement=placement)
  File "C:\Users\McKewJ\Anaconda\envs\AirQualityToolkit\lib\site-packages\pandas\core\internals.py", line 125, in __init__
    '{mgr}'.format(val=len(self.values), mgr=len(self.mgr_locs)))
ValueError: Wrong number of items passed 2, placement implies 1
2018-11-30 10:18:13 ERROR    Traceback (most recent call last):
  File "C:\Users\McKewJ\Anaconda\envs\AirQualityToolkit\lib\site-packages\pandas\core\indexes\base.py", line 3078, in get_loc
    return self._engine.get_loc(key)
  File "pandas/_libs/index.pyx", line 140, in pandas._libs.index.IndexEngine.get_loc
  File "pandas/_libs/index.pyx", line 162, in pandas._libs.index.IndexEngine.get_loc
  File "pandas/_libs/hashtable_class_helper.pxi", line 1492, in pandas._libs.hashtable.PyObjectHashTable.get_item
  File "pandas/_libs/hashtable_class_helper.pxi", line 1500, in pandas._libs.hashtable.PyObjectHashTable.get_item
KeyError: 'background'

During handling of the above exception, another exception occurred:

Traceback (most recent call last):
  File "C:\Users\McKewJ\Anaconda\envs\AirQualityToolkit\lib\site-packages\pandas\core\internals.py", line 4243, in set
    loc = self.items.get_loc(item)
  File "C:\Users\McKewJ\Anaconda\envs\AirQualityToolkit\lib\site-packages\pandas\core\indexes\base.py", line 3080, in get_loc
    return self._engine.get_loc(self._maybe_cast_indexer(key))
  File "pandas/_libs/index.pyx", line 140, in pandas._libs.index.IndexEngine.get_loc
  File "pandas/_libs/index.pyx", line 162, in pandas._libs.index.IndexEngine.get_loc
  File "pandas/_libs/hashtable_class_helper.pxi", line 1492, in pandas._libs.hashtable.PyObjectHashTable.get_item
  File "pandas/_libs/hashtable_class_helper.pxi", line 1500, in pandas._libs.hashtable.PyObjectHashTable.get_item
KeyError: 'background'

During handling of the above exception, another exception occurred:

Traceback (most recent call last):
  File "u:\Git Version Control\Air-Quality-Toolkit\modules\Contemporaneous.py", line 43, in contemporaneous
    data['background'] = background.iloc[:,header_length:]
  File "C:\Users\McKewJ\Anaconda\envs\AirQualityToolkit\lib\site-packages\pandas\core\frame.py", line 3119, in __setitem__
    self._set_item(key, value)
  File "C:\Users\McKewJ\Anaconda\envs\AirQualityToolkit\lib\site-packages\pandas\core\frame.py", line 3195, in _set_item
    NDFrame._set_item(self, key, value)
  File "C:\Users\McKewJ\Anaconda\envs\AirQualityToolkit\lib\site-packages\pandas\core\generic.py", line 2600, in _set_item
    self._data.set(key, value)
  File "C:\Users\McKewJ\Anaconda\envs\AirQualityToolkit\lib\site-packages\pandas\core\internals.py", line 4246, in set
    self.insert(len(self.items), item, value)
  File "C:\Users\McKewJ\Anaconda\envs\AirQualityToolkit\lib\site-packages\pandas\core\internals.py", line 4347, in insert
    placement=slice(loc, loc + 1))
  File "C:\Users\McKewJ\Anaconda\envs\AirQualityToolkit\lib\site-packages\pandas\core\internals.py", line 3205, in make_block
    return klass(values, ndim=ndim, placement=placement)
  File "C:\Users\McKewJ\Anaconda\envs\AirQualityToolkit\lib\site-packages\pandas\core\internals.py", line 125, in __init__
    '{mgr}'.format(val=len(self.values), mgr=len(self.mgr_locs)))
ValueError: Wrong number of items passed 2, placement implies 1
Traceback (most recent call last):
  File "C:\Users\McKewJ\Anaconda\envs\AirQualityToolkit\lib\site-packages\pandas\core\indexes\base.py", line 3078, in get_loc
    return self._engine.get_loc(key)
  File "pandas/_libs/index.pyx", line 140, in pandas._libs.index.IndexEngine.get_loc
  File "pandas/_libs/index.pyx", line 162, in pandas._libs.index.IndexEngine.get_loc
  File "pandas/_libs/hashtable_class_helper.pxi", line 1492, in pandas._libs.hashtable.PyObjectHashTable.get_item
  File "pandas/_libs/hashtable_class_helper.pxi", line 1500, in pandas._libs.hashtable.PyObjectHashTable.get_item
KeyError: 'background'

During handling of the above exception, another exception occurred:

Traceback (most recent call last):
  File "C:\Users\McKewJ\Anaconda\envs\AirQualityToolkit\lib\site-packages\pandas\core\internals.py", line 4243, in set
    loc = self.items.get_loc(item)
  File "C:\Users\McKewJ\Anaconda\envs\AirQualityToolkit\lib\site-packages\pandas\core\indexes\base.py", line 3080, in get_loc
    return self._engine.get_loc(self._maybe_cast_indexer(key))
  File "pandas/_libs/index.pyx", line 140, in pandas._libs.index.IndexEngine.get_loc
  File "pandas/_libs/index.pyx", line 162, in pandas._libs.index.IndexEngine.get_loc
  File "pandas/_libs/hashtable_class_helper.pxi", line 1492, in pandas._libs.hashtable.PyObjectHashTable.get_item
  File "pandas/_libs/hashtable_class_helper.pxi", line 1500, in pandas._libs.hashtable.PyObjectHashTable.get_item
KeyError: 'background'

During handling of the above exception, another exception occurred:

Traceback (most recent call last):
  File "u:\Git Version Control\Air-Quality-Toolkit\modules\Contemporaneous.py", line 43, in contemporaneous
    data['background'] = background.iloc[:,header_length:]
  File "C:\Users\McKewJ\Anaconda\envs\AirQualityToolkit\lib\site-packages\pandas\core\frame.py", line 3119, in __setitem__
    self._set_item(key, value)
  File "C:\Users\McKewJ\Anaconda\envs\AirQualityToolkit\lib\site-packages\pandas\core\frame.py", line 3195, in _set_item
    NDFrame._set_item(self, key, value)
  File "C:\Users\McKewJ\Anaconda\envs\AirQualityToolkit\lib\site-packages\pandas\core\generic.py", line 2600, in _set_item
    self._data.set(key, value)
  File "C:\Users\McKewJ\Anaconda\envs\AirQualityToolkit\lib\site-packages\pandas\core\internals.py", line 4246, in set
    self.insert(len(self.items), item, value)
  File "C:\Users\McKewJ\Anaconda\envs\AirQualityToolkit\lib\site-packages\pandas\core\internals.py", line 4347, in insert
    placement=slice(loc, loc + 1))
  File "C:\Users\McKewJ\Anaconda\envs\AirQualityToolkit\lib\site-packages\pandas\core\internals.py", line 3205, in make_block
    return klass(values, ndim=ndim, placement=placement)
  File "C:\Users\McKewJ\Anaconda\envs\AirQualityToolkit\lib\site-packages\pandas\core\internals.py", line 125, in __init__
    '{mgr}'.format(val=len(self.values), mgr=len(self.mgr_locs)))
ValueError: Wrong number of items passed 2, placement implies 1
2018-11-30 10:20:56 ERROR    Traceback (most recent call last):
  File "C:\Users\McKewJ\Anaconda\envs\AirQualityToolkit\lib\site-packages\pandas\core\indexes\base.py", line 3078, in get_loc
    return self._engine.get_loc(key)
  File "pandas/_libs/index.pyx", line 140, in pandas._libs.index.IndexEngine.get_loc
  File "pandas/_libs/index.pyx", line 162, in pandas._libs.index.IndexEngine.get_loc
  File "pandas/_libs/hashtable_class_helper.pxi", line 1492, in pandas._libs.hashtable.PyObjectHashTable.get_item
  File "pandas/_libs/hashtable_class_helper.pxi", line 1500, in pandas._libs.hashtable.PyObjectHashTable.get_item
KeyError: 'background'

During handling of the above exception, another exception occurred:

Traceback (most recent call last):
  File "C:\Users\McKewJ\Anaconda\envs\AirQualityToolkit\lib\site-packages\pandas\core\internals.py", line 4243, in set
    loc = self.items.get_loc(item)
  File "C:\Users\McKewJ\Anaconda\envs\AirQualityToolkit\lib\site-packages\pandas\core\indexes\base.py", line 3080, in get_loc
    return self._engine.get_loc(self._maybe_cast_indexer(key))
  File "pandas/_libs/index.pyx", line 140, in pandas._libs.index.IndexEngine.get_loc
  File "pandas/_libs/index.pyx", line 162, in pandas._libs.index.IndexEngine.get_loc
  File "pandas/_libs/hashtable_class_helper.pxi", line 1492, in pandas._libs.hashtable.PyObjectHashTable.get_item
  File "pandas/_libs/hashtable_class_helper.pxi", line 1500, in pandas._libs.hashtable.PyObjectHashTable.get_item
KeyError: 'background'

During handling of the above exception, another exception occurred:

Traceback (most recent call last):
  File "u:\Git Version Control\Air-Quality-Toolkit\modules\Contemporaneous.py", line 43, in contemporaneous
    data['background'] = background.iloc[:,header_length:]
  File "C:\Users\McKewJ\Anaconda\envs\AirQualityToolkit\lib\site-packages\pandas\core\frame.py", line 3119, in __setitem__
    self._set_item(key, value)
  File "C:\Users\McKewJ\Anaconda\envs\AirQualityToolkit\lib\site-packages\pandas\core\frame.py", line 3195, in _set_item
    NDFrame._set_item(self, key, value)
  File "C:\Users\McKewJ\Anaconda\envs\AirQualityToolkit\lib\site-packages\pandas\core\generic.py", line 2600, in _set_item
    self._data.set(key, value)
  File "C:\Users\McKewJ\Anaconda\envs\AirQualityToolkit\lib\site-packages\pandas\core\internals.py", line 4246, in set
    self.insert(len(self.items), item, value)
  File "C:\Users\McKewJ\Anaconda\envs\AirQualityToolkit\lib\site-packages\pandas\core\internals.py", line 4347, in insert
    placement=slice(loc, loc + 1))
  File "C:\Users\McKewJ\Anaconda\envs\AirQualityToolkit\lib\site-packages\pandas\core\internals.py", line 3205, in make_block
    return klass(values, ndim=ndim, placement=placement)
  File "C:\Users\McKewJ\Anaconda\envs\AirQualityToolkit\lib\site-packages\pandas\core\internals.py", line 125, in __init__
    '{mgr}'.format(val=len(self.values), mgr=len(self.mgr_locs)))
ValueError: Wrong number of items passed 2, placement implies 1
Traceback (most recent call last):
  File "C:\Users\McKewJ\Anaconda\envs\AirQualityToolkit\lib\site-packages\pandas\core\indexes\base.py", line 3078, in get_loc
    return self._engine.get_loc(key)
  File "pandas/_libs/index.pyx", line 140, in pandas._libs.index.IndexEngine.get_loc
  File "pandas/_libs/index.pyx", line 162, in pandas._libs.index.IndexEngine.get_loc
  File "pandas/_libs/hashtable_class_helper.pxi", line 1492, in pandas._libs.hashtable.PyObjectHashTable.get_item
  File "pandas/_libs/hashtable_class_helper.pxi", line 1500, in pandas._libs.hashtable.PyObjectHashTable.get_item
KeyError: 'background'

During handling of the above exception, another exception occurred:

Traceback (most recent call last):
  File "C:\Users\McKewJ\Anaconda\envs\AirQualityToolkit\lib\site-packages\pandas\core\internals.py", line 4243, in set
    loc = self.items.get_loc(item)
  File "C:\Users\McKewJ\Anaconda\envs\AirQualityToolkit\lib\site-packages\pandas\core\indexes\base.py", line 3080, in get_loc
    return self._engine.get_loc(self._maybe_cast_indexer(key))
  File "pandas/_libs/index.pyx", line 140, in pandas._libs.index.IndexEngine.get_loc
  File "pandas/_libs/index.pyx", line 162, in pandas._libs.index.IndexEngine.get_loc
  File "pandas/_libs/hashtable_class_helper.pxi", line 1492, in pandas._libs.hashtable.PyObjectHashTable.get_item
  File "pandas/_libs/hashtable_class_helper.pxi", line 1500, in pandas._libs.hashtable.PyObjectHashTable.get_item
KeyError: 'background'

During handling of the above exception, another exception occurred:

Traceback (most recent call last):
  File "u:\Git Version Control\Air-Quality-Toolkit\modules\Contemporaneous.py", line 43, in contemporaneous
    data['background'] = background.iloc[:,header_length:]
  File "C:\Users\McKewJ\Anaconda\envs\AirQualityToolkit\lib\site-packages\pandas\core\frame.py", line 3119, in __setitem__
    self._set_item(key, value)
  File "C:\Users\McKewJ\Anaconda\envs\AirQualityToolkit\lib\site-packages\pandas\core\frame.py", line 3195, in _set_item
    NDFrame._set_item(self, key, value)
  File "C:\Users\McKewJ\Anaconda\envs\AirQualityToolkit\lib\site-packages\pandas\core\generic.py", line 2600, in _set_item
    self._data.set(key, value)
  File "C:\Users\McKewJ\Anaconda\envs\AirQualityToolkit\lib\site-packages\pandas\core\internals.py", line 4246, in set
    self.insert(len(self.items), item, value)
  File "C:\Users\McKewJ\Anaconda\envs\AirQualityToolkit\lib\site-packages\pandas\core\internals.py", line 4347, in insert
    placement=slice(loc, loc + 1))
  File "C:\Users\McKewJ\Anaconda\envs\AirQualityToolkit\lib\site-packages\pandas\core\internals.py", line 3205, in make_block
    return klass(values, ndim=ndim, placement=placement)
  File "C:\Users\McKewJ\Anaconda\envs\AirQualityToolkit\lib\site-packages\pandas\core\internals.py", line 125, in __init__
    '{mgr}'.format(val=len(self.values), mgr=len(self.mgr_locs)))
ValueError: Wrong number of items passed 2, placement implies 1
2018-11-30 10:20:56 ERROR    Traceback (most recent call last):
  File "C:\Users\McKewJ\Anaconda\envs\AirQualityToolkit\lib\site-packages\pandas\core\indexes\base.py", line 3078, in get_loc
    return self._engine.get_loc(key)
  File "pandas/_libs/index.pyx", line 140, in pandas._libs.index.IndexEngine.get_loc
  File "pandas/_libs/index.pyx", line 162, in pandas._libs.index.IndexEngine.get_loc
  File "pandas/_libs/hashtable_class_helper.pxi", line 1492, in pandas._libs.hashtable.PyObjectHashTable.get_item
  File "pandas/_libs/hashtable_class_helper.pxi", line 1500, in pandas._libs.hashtable.PyObjectHashTable.get_item
KeyError: 'background'

During handling of the above exception, another exception occurred:

Traceback (most recent call last):
  File "C:\Users\McKewJ\Anaconda\envs\AirQualityToolkit\lib\site-packages\pandas\core\internals.py", line 4243, in set
    loc = self.items.get_loc(item)
  File "C:\Users\McKewJ\Anaconda\envs\AirQualityToolkit\lib\site-packages\pandas\core\indexes\base.py", line 3080, in get_loc
    return self._engine.get_loc(self._maybe_cast_indexer(key))
  File "pandas/_libs/index.pyx", line 140, in pandas._libs.index.IndexEngine.get_loc
  File "pandas/_libs/index.pyx", line 162, in pandas._libs.index.IndexEngine.get_loc
  File "pandas/_libs/hashtable_class_helper.pxi", line 1492, in pandas._libs.hashtable.PyObjectHashTable.get_item
  File "pandas/_libs/hashtable_class_helper.pxi", line 1500, in pandas._libs.hashtable.PyObjectHashTable.get_item
KeyError: 'background'

During handling of the above exception, another exception occurred:

Traceback (most recent call last):
  File "u:\Git Version Control\Air-Quality-Toolkit\modules\Contemporaneous.py", line 43, in contemporaneous
    data['background'] = background.iloc[:,header_length:]
  File "C:\Users\McKewJ\Anaconda\envs\AirQualityToolkit\lib\site-packages\pandas\core\frame.py", line 3119, in __setitem__
    self._set_item(key, value)
  File "C:\Users\McKewJ\Anaconda\envs\AirQualityToolkit\lib\site-packages\pandas\core\frame.py", line 3195, in _set_item
    NDFrame._set_item(self, key, value)
  File "C:\Users\McKewJ\Anaconda\envs\AirQualityToolkit\lib\site-packages\pandas\core\generic.py", line 2600, in _set_item
    self._data.set(key, value)
  File "C:\Users\McKewJ\Anaconda\envs\AirQualityToolkit\lib\site-packages\pandas\core\internals.py", line 4246, in set
    self.insert(len(self.items), item, value)
  File "C:\Users\McKewJ\Anaconda\envs\AirQualityToolkit\lib\site-packages\pandas\core\internals.py", line 4347, in insert
    placement=slice(loc, loc + 1))
  File "C:\Users\McKewJ\Anaconda\envs\AirQualityToolkit\lib\site-packages\pandas\core\internals.py", line 3205, in make_block
    return klass(values, ndim=ndim, placement=placement)
  File "C:\Users\McKewJ\Anaconda\envs\AirQualityToolkit\lib\site-packages\pandas\core\internals.py", line 125, in __init__
    '{mgr}'.format(val=len(self.values), mgr=len(self.mgr_locs)))
ValueError: Wrong number of items passed 2, placement implies 1
Traceback (most recent call last):
  File "C:\Users\McKewJ\Anaconda\envs\AirQualityToolkit\lib\site-packages\pandas\core\indexes\base.py", line 3078, in get_loc
    return self._engine.get_loc(key)
  File "pandas/_libs/index.pyx", line 140, in pandas._libs.index.IndexEngine.get_loc
  File "pandas/_libs/index.pyx", line 162, in pandas._libs.index.IndexEngine.get_loc
  File "pandas/_libs/hashtable_class_helper.pxi", line 1492, in pandas._libs.hashtable.PyObjectHashTable.get_item
  File "pandas/_libs/hashtable_class_helper.pxi", line 1500, in pandas._libs.hashtable.PyObjectHashTable.get_item
KeyError: 'background'

During handling of the above exception, another exception occurred:

Traceback (most recent call last):
  File "C:\Users\McKewJ\Anaconda\envs\AirQualityToolkit\lib\site-packages\pandas\core\internals.py", line 4243, in set
    loc = self.items.get_loc(item)
  File "C:\Users\McKewJ\Anaconda\envs\AirQualityToolkit\lib\site-packages\pandas\core\indexes\base.py", line 3080, in get_loc
    return self._engine.get_loc(self._maybe_cast_indexer(key))
  File "pandas/_libs/index.pyx", line 140, in pandas._libs.index.IndexEngine.get_loc
  File "pandas/_libs/index.pyx", line 162, in pandas._libs.index.IndexEngine.get_loc
  File "pandas/_libs/hashtable_class_helper.pxi", line 1492, in pandas._libs.hashtable.PyObjectHashTable.get_item
  File "pandas/_libs/hashtable_class_helper.pxi", line 1500, in pandas._libs.hashtable.PyObjectHashTable.get_item
KeyError: 'background'

During handling of the above exception, another exception occurred:

Traceback (most recent call last):
  File "u:\Git Version Control\Air-Quality-Toolkit\modules\Contemporaneous.py", line 43, in contemporaneous
    data['background'] = background.iloc[:,header_length:]
  File "C:\Users\McKewJ\Anaconda\envs\AirQualityToolkit\lib\site-packages\pandas\core\frame.py", line 3119, in __setitem__
    self._set_item(key, value)
  File "C:\Users\McKewJ\Anaconda\envs\AirQualityToolkit\lib\site-packages\pandas\core\frame.py", line 3195, in _set_item
    NDFrame._set_item(self, key, value)
  File "C:\Users\McKewJ\Anaconda\envs\AirQualityToolkit\lib\site-packages\pandas\core\generic.py", line 2600, in _set_item
    self._data.set(key, value)
  File "C:\Users\McKewJ\Anaconda\envs\AirQualityToolkit\lib\site-packages\pandas\core\internals.py", line 4246, in set
    self.insert(len(self.items), item, value)
  File "C:\Users\McKewJ\Anaconda\envs\AirQualityToolkit\lib\site-packages\pandas\core\internals.py", line 4347, in insert
    placement=slice(loc, loc + 1))
  File "C:\Users\McKewJ\Anaconda\envs\AirQualityToolkit\lib\site-packages\pandas\core\internals.py", line 3205, in make_block
    return klass(values, ndim=ndim, placement=placement)
  File "C:\Users\McKewJ\Anaconda\envs\AirQualityToolkit\lib\site-packages\pandas\core\internals.py", line 125, in __init__
    '{mgr}'.format(val=len(self.values), mgr=len(self.mgr_locs)))
ValueError: Wrong number of items passed 2, placement implies 1
2018-11-30 10:22:36 ERROR    Traceback (most recent call last):
  File "C:\Users\McKewJ\Anaconda\envs\AirQualityToolkit\lib\site-packages\pandas\core\indexes\base.py", line 3078, in get_loc
    return self._engine.get_loc(key)
  File "pandas/_libs/index.pyx", line 140, in pandas._libs.index.IndexEngine.get_loc
  File "pandas/_libs/index.pyx", line 162, in pandas._libs.index.IndexEngine.get_loc
  File "pandas/_libs/hashtable_class_helper.pxi", line 1492, in pandas._libs.hashtable.PyObjectHashTable.get_item
  File "pandas/_libs/hashtable_class_helper.pxi", line 1500, in pandas._libs.hashtable.PyObjectHashTable.get_item
KeyError: 'background'

During handling of the above exception, another exception occurred:

Traceback (most recent call last):
  File "C:\Users\McKewJ\Anaconda\envs\AirQualityToolkit\lib\site-packages\pandas\core\internals.py", line 4243, in set
    loc = self.items.get_loc(item)
  File "C:\Users\McKewJ\Anaconda\envs\AirQualityToolkit\lib\site-packages\pandas\core\indexes\base.py", line 3080, in get_loc
    return self._engine.get_loc(self._maybe_cast_indexer(key))
  File "pandas/_libs/index.pyx", line 140, in pandas._libs.index.IndexEngine.get_loc
  File "pandas/_libs/index.pyx", line 162, in pandas._libs.index.IndexEngine.get_loc
  File "pandas/_libs/hashtable_class_helper.pxi", line 1492, in pandas._libs.hashtable.PyObjectHashTable.get_item
  File "pandas/_libs/hashtable_class_helper.pxi", line 1500, in pandas._libs.hashtable.PyObjectHashTable.get_item
KeyError: 'background'

During handling of the above exception, another exception occurred:

Traceback (most recent call last):
  File "u:\Git Version Control\Air-Quality-Toolkit\modules\Contemporaneous.py", line 43, in contemporaneous
    data['background'] = background.iloc[:,header_length:]
  File "C:\Users\McKewJ\Anaconda\envs\AirQualityToolkit\lib\site-packages\pandas\core\frame.py", line 3119, in __setitem__
    self._set_item(key, value)
  File "C:\Users\McKewJ\Anaconda\envs\AirQualityToolkit\lib\site-packages\pandas\core\frame.py", line 3195, in _set_item
    NDFrame._set_item(self, key, value)
  File "C:\Users\McKewJ\Anaconda\envs\AirQualityToolkit\lib\site-packages\pandas\core\generic.py", line 2600, in _set_item
    self._data.set(key, value)
  File "C:\Users\McKewJ\Anaconda\envs\AirQualityToolkit\lib\site-packages\pandas\core\internals.py", line 4246, in set
    self.insert(len(self.items), item, value)
  File "C:\Users\McKewJ\Anaconda\envs\AirQualityToolkit\lib\site-packages\pandas\core\internals.py", line 4347, in insert
    placement=slice(loc, loc + 1))
  File "C:\Users\McKewJ\Anaconda\envs\AirQualityToolkit\lib\site-packages\pandas\core\internals.py", line 3205, in make_block
    return klass(values, ndim=ndim, placement=placement)
  File "C:\Users\McKewJ\Anaconda\envs\AirQualityToolkit\lib\site-packages\pandas\core\internals.py", line 125, in __init__
    '{mgr}'.format(val=len(self.values), mgr=len(self.mgr_locs)))
ValueError: Wrong number of items passed 2, placement implies 1
Traceback (most recent call last):
  File "C:\Users\McKewJ\Anaconda\envs\AirQualityToolkit\lib\site-packages\pandas\core\indexes\base.py", line 3078, in get_loc
    return self._engine.get_loc(key)
  File "pandas/_libs/index.pyx", line 140, in pandas._libs.index.IndexEngine.get_loc
  File "pandas/_libs/index.pyx", line 162, in pandas._libs.index.IndexEngine.get_loc
  File "pandas/_libs/hashtable_class_helper.pxi", line 1492, in pandas._libs.hashtable.PyObjectHashTable.get_item
  File "pandas/_libs/hashtable_class_helper.pxi", line 1500, in pandas._libs.hashtable.PyObjectHashTable.get_item
KeyError: 'background'

During handling of the above exception, another exception occurred:

Traceback (most recent call last):
  File "C:\Users\McKewJ\Anaconda\envs\AirQualityToolkit\lib\site-packages\pandas\core\internals.py", line 4243, in set
    loc = self.items.get_loc(item)
  File "C:\Users\McKewJ\Anaconda\envs\AirQualityToolkit\lib\site-packages\pandas\core\indexes\base.py", line 3080, in get_loc
    return self._engine.get_loc(self._maybe_cast_indexer(key))
  File "pandas/_libs/index.pyx", line 140, in pandas._libs.index.IndexEngine.get_loc
  File "pandas/_libs/index.pyx", line 162, in pandas._libs.index.IndexEngine.get_loc
  File "pandas/_libs/hashtable_class_helper.pxi", line 1492, in pandas._libs.hashtable.PyObjectHashTable.get_item
  File "pandas/_libs/hashtable_class_helper.pxi", line 1500, in pandas._libs.hashtable.PyObjectHashTable.get_item
KeyError: 'background'

During handling of the above exception, another exception occurred:

Traceback (most recent call last):
  File "u:\Git Version Control\Air-Quality-Toolkit\modules\Contemporaneous.py", line 43, in contemporaneous
    data['background'] = background.iloc[:,header_length:]
  File "C:\Users\McKewJ\Anaconda\envs\AirQualityToolkit\lib\site-packages\pandas\core\frame.py", line 3119, in __setitem__
    self._set_item(key, value)
  File "C:\Users\McKewJ\Anaconda\envs\AirQualityToolkit\lib\site-packages\pandas\core\frame.py", line 3195, in _set_item
    NDFrame._set_item(self, key, value)
  File "C:\Users\McKewJ\Anaconda\envs\AirQualityToolkit\lib\site-packages\pandas\core\generic.py", line 2600, in _set_item
    self._data.set(key, value)
  File "C:\Users\McKewJ\Anaconda\envs\AirQualityToolkit\lib\site-packages\pandas\core\internals.py", line 4246, in set
    self.insert(len(self.items), item, value)
  File "C:\Users\McKewJ\Anaconda\envs\AirQualityToolkit\lib\site-packages\pandas\core\internals.py", line 4347, in insert
    placement=slice(loc, loc + 1))
  File "C:\Users\McKewJ\Anaconda\envs\AirQualityToolkit\lib\site-packages\pandas\core\internals.py", line 3205, in make_block
    return klass(values, ndim=ndim, placement=placement)
  File "C:\Users\McKewJ\Anaconda\envs\AirQualityToolkit\lib\site-packages\pandas\core\internals.py", line 125, in __init__
    '{mgr}'.format(val=len(self.values), mgr=len(self.mgr_locs)))
ValueError: Wrong number of items passed 2, placement implies 1
2018-11-30 10:22:36 ERROR    Traceback (most recent call last):
  File "C:\Users\McKewJ\Anaconda\envs\AirQualityToolkit\lib\site-packages\pandas\core\indexes\base.py", line 3078, in get_loc
    return self._engine.get_loc(key)
  File "pandas/_libs/index.pyx", line 140, in pandas._libs.index.IndexEngine.get_loc
  File "pandas/_libs/index.pyx", line 162, in pandas._libs.index.IndexEngine.get_loc
  File "pandas/_libs/hashtable_class_helper.pxi", line 1492, in pandas._libs.hashtable.PyObjectHashTable.get_item
  File "pandas/_libs/hashtable_class_helper.pxi", line 1500, in pandas._libs.hashtable.PyObjectHashTable.get_item
KeyError: 'background'

During handling of the above exception, another exception occurred:

Traceback (most recent call last):
  File "C:\Users\McKewJ\Anaconda\envs\AirQualityToolkit\lib\site-packages\pandas\core\internals.py", line 4243, in set
    loc = self.items.get_loc(item)
  File "C:\Users\McKewJ\Anaconda\envs\AirQualityToolkit\lib\site-packages\pandas\core\indexes\base.py", line 3080, in get_loc
    return self._engine.get_loc(self._maybe_cast_indexer(key))
  File "pandas/_libs/index.pyx", line 140, in pandas._libs.index.IndexEngine.get_loc
  File "pandas/_libs/index.pyx", line 162, in pandas._libs.index.IndexEngine.get_loc
  File "pandas/_libs/hashtable_class_helper.pxi", line 1492, in pandas._libs.hashtable.PyObjectHashTable.get_item
  File "pandas/_libs/hashtable_class_helper.pxi", line 1500, in pandas._libs.hashtable.PyObjectHashTable.get_item
KeyError: 'background'

During handling of the above exception, another exception occurred:

Traceback (most recent call last):
  File "u:\Git Version Control\Air-Quality-Toolkit\modules\Contemporaneous.py", line 43, in contemporaneous
    data['background'] = background.iloc[:,header_length:]
  File "C:\Users\McKewJ\Anaconda\envs\AirQualityToolkit\lib\site-packages\pandas\core\frame.py", line 3119, in __setitem__
    self._set_item(key, value)
  File "C:\Users\McKewJ\Anaconda\envs\AirQualityToolkit\lib\site-packages\pandas\core\frame.py", line 3195, in _set_item
    NDFrame._set_item(self, key, value)
  File "C:\Users\McKewJ\Anaconda\envs\AirQualityToolkit\lib\site-packages\pandas\core\generic.py", line 2600, in _set_item
    self._data.set(key, value)
  File "C:\Users\McKewJ\Anaconda\envs\AirQualityToolkit\lib\site-packages\pandas\core\internals.py", line 4246, in set
    self.insert(len(self.items), item, value)
  File "C:\Users\McKewJ\Anaconda\envs\AirQualityToolkit\lib\site-packages\pandas\core\internals.py", line 4347, in insert
    placement=slice(loc, loc + 1))
  File "C:\Users\McKewJ\Anaconda\envs\AirQualityToolkit\lib\site-packages\pandas\core\internals.py", line 3205, in make_block
    return klass(values, ndim=ndim, placement=placement)
  File "C:\Users\McKewJ\Anaconda\envs\AirQualityToolkit\lib\site-packages\pandas\core\internals.py", line 125, in __init__
    '{mgr}'.format(val=len(self.values), mgr=len(self.mgr_locs)))
ValueError: Wrong number of items passed 2, placement implies 1
Traceback (most recent call last):
  File "C:\Users\McKewJ\Anaconda\envs\AirQualityToolkit\lib\site-packages\pandas\core\indexes\base.py", line 3078, in get_loc
    return self._engine.get_loc(key)
  File "pandas/_libs/index.pyx", line 140, in pandas._libs.index.IndexEngine.get_loc
  File "pandas/_libs/index.pyx", line 162, in pandas._libs.index.IndexEngine.get_loc
  File "pandas/_libs/hashtable_class_helper.pxi", line 1492, in pandas._libs.hashtable.PyObjectHashTable.get_item
  File "pandas/_libs/hashtable_class_helper.pxi", line 1500, in pandas._libs.hashtable.PyObjectHashTable.get_item
KeyError: 'background'

During handling of the above exception, another exception occurred:

Traceback (most recent call last):
  File "C:\Users\McKewJ\Anaconda\envs\AirQualityToolkit\lib\site-packages\pandas\core\internals.py", line 4243, in set
    loc = self.items.get_loc(item)
  File "C:\Users\McKewJ\Anaconda\envs\AirQualityToolkit\lib\site-packages\pandas\core\indexes\base.py", line 3080, in get_loc
    return self._engine.get_loc(self._maybe_cast_indexer(key))
  File "pandas/_libs/index.pyx", line 140, in pandas._libs.index.IndexEngine.get_loc
  File "pandas/_libs/index.pyx", line 162, in pandas._libs.index.IndexEngine.get_loc
  File "pandas/_libs/hashtable_class_helper.pxi", line 1492, in pandas._libs.hashtable.PyObjectHashTable.get_item
  File "pandas/_libs/hashtable_class_helper.pxi", line 1500, in pandas._libs.hashtable.PyObjectHashTable.get_item
KeyError: 'background'

During handling of the above exception, another exception occurred:

Traceback (most recent call last):
  File "u:\Git Version Control\Air-Quality-Toolkit\modules\Contemporaneous.py", line 43, in contemporaneous
    data['background'] = background.iloc[:,header_length:]
  File "C:\Users\McKewJ\Anaconda\envs\AirQualityToolkit\lib\site-packages\pandas\core\frame.py", line 3119, in __setitem__
    self._set_item(key, value)
  File "C:\Users\McKewJ\Anaconda\envs\AirQualityToolkit\lib\site-packages\pandas\core\frame.py", line 3195, in _set_item
    NDFrame._set_item(self, key, value)
  File "C:\Users\McKewJ\Anaconda\envs\AirQualityToolkit\lib\site-packages\pandas\core\generic.py", line 2600, in _set_item
    self._data.set(key, value)
  File "C:\Users\McKewJ\Anaconda\envs\AirQualityToolkit\lib\site-packages\pandas\core\internals.py", line 4246, in set
    self.insert(len(self.items), item, value)
  File "C:\Users\McKewJ\Anaconda\envs\AirQualityToolkit\lib\site-packages\pandas\core\internals.py", line 4347, in insert
    placement=slice(loc, loc + 1))
  File "C:\Users\McKewJ\Anaconda\envs\AirQualityToolkit\lib\site-packages\pandas\core\internals.py", line 3205, in make_block
    return klass(values, ndim=ndim, placement=placement)
  File "C:\Users\McKewJ\Anaconda\envs\AirQualityToolkit\lib\site-packages\pandas\core\internals.py", line 125, in __init__
    '{mgr}'.format(val=len(self.values), mgr=len(self.mgr_locs)))
ValueError: Wrong number of items passed 2, placement implies 1
2018-11-30 10:23:25 ERROR    Traceback (most recent call last):
  File "C:\Users\McKewJ\Anaconda\envs\AirQualityToolkit\lib\site-packages\pandas\core\indexes\base.py", line 3078, in get_loc
    return self._engine.get_loc(key)
  File "pandas/_libs/index.pyx", line 140, in pandas._libs.index.IndexEngine.get_loc
  File "pandas/_libs/index.pyx", line 162, in pandas._libs.index.IndexEngine.get_loc
  File "pandas/_libs/hashtable_class_helper.pxi", line 1492, in pandas._libs.hashtable.PyObjectHashTable.get_item
  File "pandas/_libs/hashtable_class_helper.pxi", line 1500, in pandas._libs.hashtable.PyObjectHashTable.get_item
KeyError: 'background'

During handling of the above exception, another exception occurred:

Traceback (most recent call last):
  File "C:\Users\McKewJ\Anaconda\envs\AirQualityToolkit\lib\site-packages\pandas\core\internals.py", line 4243, in set
    loc = self.items.get_loc(item)
  File "C:\Users\McKewJ\Anaconda\envs\AirQualityToolkit\lib\site-packages\pandas\core\indexes\base.py", line 3080, in get_loc
    return self._engine.get_loc(self._maybe_cast_indexer(key))
  File "pandas/_libs/index.pyx", line 140, in pandas._libs.index.IndexEngine.get_loc
  File "pandas/_libs/index.pyx", line 162, in pandas._libs.index.IndexEngine.get_loc
  File "pandas/_libs/hashtable_class_helper.pxi", line 1492, in pandas._libs.hashtable.PyObjectHashTable.get_item
  File "pandas/_libs/hashtable_class_helper.pxi", line 1500, in pandas._libs.hashtable.PyObjectHashTable.get_item
KeyError: 'background'

During handling of the above exception, another exception occurred:

Traceback (most recent call last):
  File "u:\Git Version Control\Air-Quality-Toolkit\modules\Contemporaneous.py", line 46, in contemporaneous
    data['background'] = background.iloc[:,header_length:]
  File "C:\Users\McKewJ\Anaconda\envs\AirQualityToolkit\lib\site-packages\pandas\core\frame.py", line 3119, in __setitem__
    self._set_item(key, value)
  File "C:\Users\McKewJ\Anaconda\envs\AirQualityToolkit\lib\site-packages\pandas\core\frame.py", line 3195, in _set_item
    NDFrame._set_item(self, key, value)
  File "C:\Users\McKewJ\Anaconda\envs\AirQualityToolkit\lib\site-packages\pandas\core\generic.py", line 2600, in _set_item
    self._data.set(key, value)
  File "C:\Users\McKewJ\Anaconda\envs\AirQualityToolkit\lib\site-packages\pandas\core\internals.py", line 4246, in set
    self.insert(len(self.items), item, value)
  File "C:\Users\McKewJ\Anaconda\envs\AirQualityToolkit\lib\site-packages\pandas\core\internals.py", line 4347, in insert
    placement=slice(loc, loc + 1))
  File "C:\Users\McKewJ\Anaconda\envs\AirQualityToolkit\lib\site-packages\pandas\core\internals.py", line 3205, in make_block
    return klass(values, ndim=ndim, placement=placement)
  File "C:\Users\McKewJ\Anaconda\envs\AirQualityToolkit\lib\site-packages\pandas\core\internals.py", line 125, in __init__
    '{mgr}'.format(val=len(self.values), mgr=len(self.mgr_locs)))
ValueError: Wrong number of items passed 2, placement implies 1
Traceback (most recent call last):
  File "C:\Users\McKewJ\Anaconda\envs\AirQualityToolkit\lib\site-packages\pandas\core\indexes\base.py", line 3078, in get_loc
    return self._engine.get_loc(key)
  File "pandas/_libs/index.pyx", line 140, in pandas._libs.index.IndexEngine.get_loc
  File "pandas/_libs/index.pyx", line 162, in pandas._libs.index.IndexEngine.get_loc
  File "pandas/_libs/hashtable_class_helper.pxi", line 1492, in pandas._libs.hashtable.PyObjectHashTable.get_item
  File "pandas/_libs/hashtable_class_helper.pxi", line 1500, in pandas._libs.hashtable.PyObjectHashTable.get_item
KeyError: 'background'

During handling of the above exception, another exception occurred:

Traceback (most recent call last):
  File "C:\Users\McKewJ\Anaconda\envs\AirQualityToolkit\lib\site-packages\pandas\core\internals.py", line 4243, in set
    loc = self.items.get_loc(item)
  File "C:\Users\McKewJ\Anaconda\envs\AirQualityToolkit\lib\site-packages\pandas\core\indexes\base.py", line 3080, in get_loc
    return self._engine.get_loc(self._maybe_cast_indexer(key))
  File "pandas/_libs/index.pyx", line 140, in pandas._libs.index.IndexEngine.get_loc
  File "pandas/_libs/index.pyx", line 162, in pandas._libs.index.IndexEngine.get_loc
  File "pandas/_libs/hashtable_class_helper.pxi", line 1492, in pandas._libs.hashtable.PyObjectHashTable.get_item
  File "pandas/_libs/hashtable_class_helper.pxi", line 1500, in pandas._libs.hashtable.PyObjectHashTable.get_item
KeyError: 'background'

During handling of the above exception, another exception occurred:

Traceback (most recent call last):
  File "u:\Git Version Control\Air-Quality-Toolkit\modules\Contemporaneous.py", line 46, in contemporaneous
    data['background'] = background.iloc[:,header_length:]
  File "C:\Users\McKewJ\Anaconda\envs\AirQualityToolkit\lib\site-packages\pandas\core\frame.py", line 3119, in __setitem__
    self._set_item(key, value)
  File "C:\Users\McKewJ\Anaconda\envs\AirQualityToolkit\lib\site-packages\pandas\core\frame.py", line 3195, in _set_item
    NDFrame._set_item(self, key, value)
  File "C:\Users\McKewJ\Anaconda\envs\AirQualityToolkit\lib\site-packages\pandas\core\generic.py", line 2600, in _set_item
    self._data.set(key, value)
  File "C:\Users\McKewJ\Anaconda\envs\AirQualityToolkit\lib\site-packages\pandas\core\internals.py", line 4246, in set
    self.insert(len(self.items), item, value)
  File "C:\Users\McKewJ\Anaconda\envs\AirQualityToolkit\lib\site-packages\pandas\core\internals.py", line 4347, in insert
    placement=slice(loc, loc + 1))
  File "C:\Users\McKewJ\Anaconda\envs\AirQualityToolkit\lib\site-packages\pandas\core\internals.py", line 3205, in make_block
    return klass(values, ndim=ndim, placement=placement)
  File "C:\Users\McKewJ\Anaconda\envs\AirQualityToolkit\lib\site-packages\pandas\core\internals.py", line 125, in __init__
    '{mgr}'.format(val=len(self.values), mgr=len(self.mgr_locs)))
ValueError: Wrong number of items passed 2, placement implies 1
2018-11-30 10:23:25 ERROR    Traceback (most recent call last):
  File "C:\Users\McKewJ\Anaconda\envs\AirQualityToolkit\lib\site-packages\pandas\core\indexes\base.py", line 3078, in get_loc
    return self._engine.get_loc(key)
  File "pandas/_libs/index.pyx", line 140, in pandas._libs.index.IndexEngine.get_loc
  File "pandas/_libs/index.pyx", line 162, in pandas._libs.index.IndexEngine.get_loc
  File "pandas/_libs/hashtable_class_helper.pxi", line 1492, in pandas._libs.hashtable.PyObjectHashTable.get_item
  File "pandas/_libs/hashtable_class_helper.pxi", line 1500, in pandas._libs.hashtable.PyObjectHashTable.get_item
KeyError: 'background'

During handling of the above exception, another exception occurred:

Traceback (most recent call last):
  File "C:\Users\McKewJ\Anaconda\envs\AirQualityToolkit\lib\site-packages\pandas\core\internals.py", line 4243, in set
    loc = self.items.get_loc(item)
  File "C:\Users\McKewJ\Anaconda\envs\AirQualityToolkit\lib\site-packages\pandas\core\indexes\base.py", line 3080, in get_loc
    return self._engine.get_loc(self._maybe_cast_indexer(key))
  File "pandas/_libs/index.pyx", line 140, in pandas._libs.index.IndexEngine.get_loc
  File "pandas/_libs/index.pyx", line 162, in pandas._libs.index.IndexEngine.get_loc
  File "pandas/_libs/hashtable_class_helper.pxi", line 1492, in pandas._libs.hashtable.PyObjectHashTable.get_item
  File "pandas/_libs/hashtable_class_helper.pxi", line 1500, in pandas._libs.hashtable.PyObjectHashTable.get_item
KeyError: 'background'

During handling of the above exception, another exception occurred:

Traceback (most recent call last):
  File "u:\Git Version Control\Air-Quality-Toolkit\modules\Contemporaneous.py", line 46, in contemporaneous
    data['background'] = background.iloc[:,header_length:]
  File "C:\Users\McKewJ\Anaconda\envs\AirQualityToolkit\lib\site-packages\pandas\core\frame.py", line 3119, in __setitem__
    self._set_item(key, value)
  File "C:\Users\McKewJ\Anaconda\envs\AirQualityToolkit\lib\site-packages\pandas\core\frame.py", line 3195, in _set_item
    NDFrame._set_item(self, key, value)
  File "C:\Users\McKewJ\Anaconda\envs\AirQualityToolkit\lib\site-packages\pandas\core\generic.py", line 2600, in _set_item
    self._data.set(key, value)
  File "C:\Users\McKewJ\Anaconda\envs\AirQualityToolkit\lib\site-packages\pandas\core\internals.py", line 4246, in set
    self.insert(len(self.items), item, value)
  File "C:\Users\McKewJ\Anaconda\envs\AirQualityToolkit\lib\site-packages\pandas\core\internals.py", line 4347, in insert
    placement=slice(loc, loc + 1))
  File "C:\Users\McKewJ\Anaconda\envs\AirQualityToolkit\lib\site-packages\pandas\core\internals.py", line 3205, in make_block
    return klass(values, ndim=ndim, placement=placement)
  File "C:\Users\McKewJ\Anaconda\envs\AirQualityToolkit\lib\site-packages\pandas\core\internals.py", line 125, in __init__
    '{mgr}'.format(val=len(self.values), mgr=len(self.mgr_locs)))
ValueError: Wrong number of items passed 2, placement implies 1
Traceback (most recent call last):
  File "C:\Users\McKewJ\Anaconda\envs\AirQualityToolkit\lib\site-packages\pandas\core\indexes\base.py", line 3078, in get_loc
    return self._engine.get_loc(key)
  File "pandas/_libs/index.pyx", line 140, in pandas._libs.index.IndexEngine.get_loc
  File "pandas/_libs/index.pyx", line 162, in pandas._libs.index.IndexEngine.get_loc
  File "pandas/_libs/hashtable_class_helper.pxi", line 1492, in pandas._libs.hashtable.PyObjectHashTable.get_item
  File "pandas/_libs/hashtable_class_helper.pxi", line 1500, in pandas._libs.hashtable.PyObjectHashTable.get_item
KeyError: 'background'

During handling of the above exception, another exception occurred:

Traceback (most recent call last):
  File "C:\Users\McKewJ\Anaconda\envs\AirQualityToolkit\lib\site-packages\pandas\core\internals.py", line 4243, in set
    loc = self.items.get_loc(item)
  File "C:\Users\McKewJ\Anaconda\envs\AirQualityToolkit\lib\site-packages\pandas\core\indexes\base.py", line 3080, in get_loc
    return self._engine.get_loc(self._maybe_cast_indexer(key))
  File "pandas/_libs/index.pyx", line 140, in pandas._libs.index.IndexEngine.get_loc
  File "pandas/_libs/index.pyx", line 162, in pandas._libs.index.IndexEngine.get_loc
  File "pandas/_libs/hashtable_class_helper.pxi", line 1492, in pandas._libs.hashtable.PyObjectHashTable.get_item
  File "pandas/_libs/hashtable_class_helper.pxi", line 1500, in pandas._libs.hashtable.PyObjectHashTable.get_item
KeyError: 'background'

During handling of the above exception, another exception occurred:

Traceback (most recent call last):
  File "u:\Git Version Control\Air-Quality-Toolkit\modules\Contemporaneous.py", line 46, in contemporaneous
    data['background'] = background.iloc[:,header_length:]
  File "C:\Users\McKewJ\Anaconda\envs\AirQualityToolkit\lib\site-packages\pandas\core\frame.py", line 3119, in __setitem__
    self._set_item(key, value)
  File "C:\Users\McKewJ\Anaconda\envs\AirQualityToolkit\lib\site-packages\pandas\core\frame.py", line 3195, in _set_item
    NDFrame._set_item(self, key, value)
  File "C:\Users\McKewJ\Anaconda\envs\AirQualityToolkit\lib\site-packages\pandas\core\generic.py", line 2600, in _set_item
    self._data.set(key, value)
  File "C:\Users\McKewJ\Anaconda\envs\AirQualityToolkit\lib\site-packages\pandas\core\internals.py", line 4246, in set
    self.insert(len(self.items), item, value)
  File "C:\Users\McKewJ\Anaconda\envs\AirQualityToolkit\lib\site-packages\pandas\core\internals.py", line 4347, in insert
    placement=slice(loc, loc + 1))
  File "C:\Users\McKewJ\Anaconda\envs\AirQualityToolkit\lib\site-packages\pandas\core\internals.py", line 3205, in make_block
    return klass(values, ndim=ndim, placement=placement)
  File "C:\Users\McKewJ\Anaconda\envs\AirQualityToolkit\lib\site-packages\pandas\core\internals.py", line 125, in __init__
    '{mgr}'.format(val=len(self.values), mgr=len(self.mgr_locs)))
ValueError: Wrong number of items passed 2, placement implies 1
2018-11-30 10:24:17 ERROR    Traceback (most recent call last):
  File "u:\Git Version Control\Air-Quality-Toolkit\modules\Contemporaneous.py", line 37, in contemporaneous
    background = pd.read_csv(input_background)
  File "C:\Users\McKewJ\Anaconda\envs\AirQualityToolkit\lib\site-packages\pandas\io\parsers.py", line 678, in parser_f
    return _read(filepath_or_buffer, kwds)
  File "C:\Users\McKewJ\Anaconda\envs\AirQualityToolkit\lib\site-packages\pandas\io\parsers.py", line 440, in _read
    parser = TextFileReader(filepath_or_buffer, **kwds)
  File "C:\Users\McKewJ\Anaconda\envs\AirQualityToolkit\lib\site-packages\pandas\io\parsers.py", line 787, in __init__
    self._make_engine(self.engine)
  File "C:\Users\McKewJ\Anaconda\envs\AirQualityToolkit\lib\site-packages\pandas\io\parsers.py", line 1014, in _make_engine
    self._engine = CParserWrapper(self.f, **self.options)
  File "C:\Users\McKewJ\Anaconda\envs\AirQualityToolkit\lib\site-packages\pandas\io\parsers.py", line 1708, in __init__
    self._reader = parsers.TextReader(src, **kwds)
  File "pandas/_libs/parsers.pyx", line 384, in pandas._libs.parsers.TextReader.__cinit__
  File "pandas/_libs/parsers.pyx", line 695, in pandas._libs.parsers.TextReader._setup_parser_source
FileNotFoundError: File b'' does not exist
Traceback (most recent call last):
  File "u:\Git Version Control\Air-Quality-Toolkit\modules\Contemporaneous.py", line 37, in contemporaneous
    background = pd.read_csv(input_background)
  File "C:\Users\McKewJ\Anaconda\envs\AirQualityToolkit\lib\site-packages\pandas\io\parsers.py", line 678, in parser_f
    return _read(filepath_or_buffer, kwds)
  File "C:\Users\McKewJ\Anaconda\envs\AirQualityToolkit\lib\site-packages\pandas\io\parsers.py", line 440, in _read
    parser = TextFileReader(filepath_or_buffer, **kwds)
  File "C:\Users\McKewJ\Anaconda\envs\AirQualityToolkit\lib\site-packages\pandas\io\parsers.py", line 787, in __init__
    self._make_engine(self.engine)
  File "C:\Users\McKewJ\Anaconda\envs\AirQualityToolkit\lib\site-packages\pandas\io\parsers.py", line 1014, in _make_engine
    self._engine = CParserWrapper(self.f, **self.options)
  File "C:\Users\McKewJ\Anaconda\envs\AirQualityToolkit\lib\site-packages\pandas\io\parsers.py", line 1708, in __init__
    self._reader = parsers.TextReader(src, **kwds)
  File "pandas/_libs/parsers.pyx", line 384, in pandas._libs.parsers.TextReader.__cinit__
  File "pandas/_libs/parsers.pyx", line 695, in pandas._libs.parsers.TextReader._setup_parser_source
FileNotFoundError: File b'' does not exist
2018-11-30 10:24:17 ERROR    Traceback (most recent call last):
  File "u:\Git Version Control\Air-Quality-Toolkit\modules\Contemporaneous.py", line 37, in contemporaneous
    background = pd.read_csv(input_background)
  File "C:\Users\McKewJ\Anaconda\envs\AirQualityToolkit\lib\site-packages\pandas\io\parsers.py", line 678, in parser_f
    return _read(filepath_or_buffer, kwds)
  File "C:\Users\McKewJ\Anaconda\envs\AirQualityToolkit\lib\site-packages\pandas\io\parsers.py", line 440, in _read
    parser = TextFileReader(filepath_or_buffer, **kwds)
  File "C:\Users\McKewJ\Anaconda\envs\AirQualityToolkit\lib\site-packages\pandas\io\parsers.py", line 787, in __init__
    self._make_engine(self.engine)
  File "C:\Users\McKewJ\Anaconda\envs\AirQualityToolkit\lib\site-packages\pandas\io\parsers.py", line 1014, in _make_engine
    self._engine = CParserWrapper(self.f, **self.options)
  File "C:\Users\McKewJ\Anaconda\envs\AirQualityToolkit\lib\site-packages\pandas\io\parsers.py", line 1708, in __init__
    self._reader = parsers.TextReader(src, **kwds)
  File "pandas/_libs/parsers.pyx", line 384, in pandas._libs.parsers.TextReader.__cinit__
  File "pandas/_libs/parsers.pyx", line 695, in pandas._libs.parsers.TextReader._setup_parser_source
FileNotFoundError: File b'' does not exist
Traceback (most recent call last):
  File "u:\Git Version Control\Air-Quality-Toolkit\modules\Contemporaneous.py", line 37, in contemporaneous
    background = pd.read_csv(input_background)
  File "C:\Users\McKewJ\Anaconda\envs\AirQualityToolkit\lib\site-packages\pandas\io\parsers.py", line 678, in parser_f
    return _read(filepath_or_buffer, kwds)
  File "C:\Users\McKewJ\Anaconda\envs\AirQualityToolkit\lib\site-packages\pandas\io\parsers.py", line 440, in _read
    parser = TextFileReader(filepath_or_buffer, **kwds)
  File "C:\Users\McKewJ\Anaconda\envs\AirQualityToolkit\lib\site-packages\pandas\io\parsers.py", line 787, in __init__
    self._make_engine(self.engine)
  File "C:\Users\McKewJ\Anaconda\envs\AirQualityToolkit\lib\site-packages\pandas\io\parsers.py", line 1014, in _make_engine
    self._engine = CParserWrapper(self.f, **self.options)
  File "C:\Users\McKewJ\Anaconda\envs\AirQualityToolkit\lib\site-packages\pandas\io\parsers.py", line 1708, in __init__
    self._reader = parsers.TextReader(src, **kwds)
  File "pandas/_libs/parsers.pyx", line 384, in pandas._libs.parsers.TextReader.__cinit__
  File "pandas/_libs/parsers.pyx", line 695, in pandas._libs.parsers.TextReader._setup_parser_source
FileNotFoundError: File b'' does not exist
2018-11-30 10:26:43 ERROR    Traceback (most recent call last):
  File "u:\Git Version Control\Air-Quality-Toolkit\modules\Contemporaneous.py", line 63, in contemporaneous
    data = data.apply(olmfunction,axis=1)
  File "C:\Users\McKewJ\Anaconda\envs\AirQualityToolkit\lib\site-packages\pandas\core\frame.py", line 6014, in apply
    return op.get_result()
  File "C:\Users\McKewJ\Anaconda\envs\AirQualityToolkit\lib\site-packages\pandas\core\apply.py", line 142, in get_result
    return self.apply_standard()
  File "C:\Users\McKewJ\Anaconda\envs\AirQualityToolkit\lib\site-packages\pandas\core\apply.py", line 248, in apply_standard
    self.apply_series_generator()
  File "C:\Users\McKewJ\Anaconda\envs\AirQualityToolkit\lib\site-packages\pandas\core\apply.py", line 277, in apply_series_generator
    results[i] = self.f(v)
  File "u:\Git Version Control\Air-Quality-Toolkit\modules\Contemporaneous.py", line 51, in olmfunction
    value = float(value)*initial + min(0.9*float(value),back)
NameError: ("name 'initial' is not defined", 'occurred at index 3')
Traceback (most recent call last):
  File "u:\Git Version Control\Air-Quality-Toolkit\modules\Contemporaneous.py", line 63, in contemporaneous
    data = data.apply(olmfunction,axis=1)
  File "C:\Users\McKewJ\Anaconda\envs\AirQualityToolkit\lib\site-packages\pandas\core\frame.py", line 6014, in apply
    return op.get_result()
  File "C:\Users\McKewJ\Anaconda\envs\AirQualityToolkit\lib\site-packages\pandas\core\apply.py", line 142, in get_result
    return self.apply_standard()
  File "C:\Users\McKewJ\Anaconda\envs\AirQualityToolkit\lib\site-packages\pandas\core\apply.py", line 248, in apply_standard
    self.apply_series_generator()
  File "C:\Users\McKewJ\Anaconda\envs\AirQualityToolkit\lib\site-packages\pandas\core\apply.py", line 277, in apply_series_generator
    results[i] = self.f(v)
  File "u:\Git Version Control\Air-Quality-Toolkit\modules\Contemporaneous.py", line 51, in olmfunction
    value = float(value)*initial + min(0.9*float(value),back)
NameError: ("name 'initial' is not defined", 'occurred at index 3')
2018-11-30 10:26:43 ERROR    Traceback (most recent call last):
  File "u:\Git Version Control\Air-Quality-Toolkit\modules\Contemporaneous.py", line 63, in contemporaneous
    data = data.apply(olmfunction,axis=1)
  File "C:\Users\McKewJ\Anaconda\envs\AirQualityToolkit\lib\site-packages\pandas\core\frame.py", line 6014, in apply
    return op.get_result()
  File "C:\Users\McKewJ\Anaconda\envs\AirQualityToolkit\lib\site-packages\pandas\core\apply.py", line 142, in get_result
    return self.apply_standard()
  File "C:\Users\McKewJ\Anaconda\envs\AirQualityToolkit\lib\site-packages\pandas\core\apply.py", line 248, in apply_standard
    self.apply_series_generator()
  File "C:\Users\McKewJ\Anaconda\envs\AirQualityToolkit\lib\site-packages\pandas\core\apply.py", line 277, in apply_series_generator
    results[i] = self.f(v)
  File "u:\Git Version Control\Air-Quality-Toolkit\modules\Contemporaneous.py", line 51, in olmfunction
    value = float(value)*initial + min(0.9*float(value),back)
NameError: ("name 'initial' is not defined", 'occurred at index 3')
Traceback (most recent call last):
  File "u:\Git Version Control\Air-Quality-Toolkit\modules\Contemporaneous.py", line 63, in contemporaneous
    data = data.apply(olmfunction,axis=1)
  File "C:\Users\McKewJ\Anaconda\envs\AirQualityToolkit\lib\site-packages\pandas\core\frame.py", line 6014, in apply
    return op.get_result()
  File "C:\Users\McKewJ\Anaconda\envs\AirQualityToolkit\lib\site-packages\pandas\core\apply.py", line 142, in get_result
    return self.apply_standard()
  File "C:\Users\McKewJ\Anaconda\envs\AirQualityToolkit\lib\site-packages\pandas\core\apply.py", line 248, in apply_standard
    self.apply_series_generator()
  File "C:\Users\McKewJ\Anaconda\envs\AirQualityToolkit\lib\site-packages\pandas\core\apply.py", line 277, in apply_series_generator
    results[i] = self.f(v)
  File "u:\Git Version Control\Air-Quality-Toolkit\modules\Contemporaneous.py", line 51, in olmfunction
    value = float(value)*initial + min(0.9*float(value),back)
NameError: ("name 'initial' is not defined", 'occurred at index 3')
2018-11-30 10:58:48 ERROR    Traceback (most recent call last):
  File "u:\Git Version Control\Air-Quality-Toolkit\modules\Contemporaneous.py", line 50, in contemporaneous
    cols = recep_headers.append(colnum)
AttributeError: 'range' object has no attribute 'append'
Traceback (most recent call last):
  File "u:\Git Version Control\Air-Quality-Toolkit\modules\Contemporaneous.py", line 50, in contemporaneous
    cols = recep_headers.append(colnum)
AttributeError: 'range' object has no attribute 'append'
2018-11-30 10:58:48 ERROR    Traceback (most recent call last):
  File "u:\Git Version Control\Air-Quality-Toolkit\modules\Contemporaneous.py", line 50, in contemporaneous
    cols = recep_headers.append(colnum)
AttributeError: 'range' object has no attribute 'append'
Traceback (most recent call last):
  File "u:\Git Version Control\Air-Quality-Toolkit\modules\Contemporaneous.py", line 50, in contemporaneous
    cols = recep_headers.append(colnum)
AttributeError: 'range' object has no attribute 'append'
2018-11-30 10:59:44 ERROR    Traceback (most recent call last):
  File "C:\Users\McKewJ\Anaconda\envs\AirQualityToolkit\lib\site-packages\pandas\core\indexing.py", line 222, in _has_valid_tuple
    self._validate_key(k, i)
  File "C:\Users\McKewJ\Anaconda\envs\AirQualityToolkit\lib\site-packages\pandas\core\indexing.py", line 1971, in _validate_key
    "a [{types}]".format(types=self._valid_types))
ValueError: Can only index by location with a [integer, integer slice (START point is INCLUDED, END point is EXCLUDED), listlike of integers, boolean array]

During handling of the above exception, another exception occurred:

Traceback (most recent call last):
  File "u:\Git Version Control\Air-Quality-Toolkit\modules\Contemporaneous.py", line 51, in contemporaneous
    receptor_con = sorted_data.iloc[:,cols]
  File "C:\Users\McKewJ\Anaconda\envs\AirQualityToolkit\lib\site-packages\pandas\core\indexing.py", line 1472, in __getitem__
    return self._getitem_tuple(key)
  File "C:\Users\McKewJ\Anaconda\envs\AirQualityToolkit\lib\site-packages\pandas\core\indexing.py", line 2013, in _getitem_tuple
    self._has_valid_tuple(tup)
  File "C:\Users\McKewJ\Anaconda\envs\AirQualityToolkit\lib\site-packages\pandas\core\indexing.py", line 226, in _has_valid_tuple
    .format(types=self._valid_types))
ValueError: Location based indexing can only have [integer, integer slice (START point is INCLUDED, END point is EXCLUDED), listlike of integers, boolean array] types
Traceback (most recent call last):
  File "C:\Users\McKewJ\Anaconda\envs\AirQualityToolkit\lib\site-packages\pandas\core\indexing.py", line 222, in _has_valid_tuple
    self._validate_key(k, i)
  File "C:\Users\McKewJ\Anaconda\envs\AirQualityToolkit\lib\site-packages\pandas\core\indexing.py", line 1971, in _validate_key
    "a [{types}]".format(types=self._valid_types))
ValueError: Can only index by location with a [integer, integer slice (START point is INCLUDED, END point is EXCLUDED), listlike of integers, boolean array]

During handling of the above exception, another exception occurred:

Traceback (most recent call last):
  File "u:\Git Version Control\Air-Quality-Toolkit\modules\Contemporaneous.py", line 51, in contemporaneous
    receptor_con = sorted_data.iloc[:,cols]
  File "C:\Users\McKewJ\Anaconda\envs\AirQualityToolkit\lib\site-packages\pandas\core\indexing.py", line 1472, in __getitem__
    return self._getitem_tuple(key)
  File "C:\Users\McKewJ\Anaconda\envs\AirQualityToolkit\lib\site-packages\pandas\core\indexing.py", line 2013, in _getitem_tuple
    self._has_valid_tuple(tup)
  File "C:\Users\McKewJ\Anaconda\envs\AirQualityToolkit\lib\site-packages\pandas\core\indexing.py", line 226, in _has_valid_tuple
    .format(types=self._valid_types))
ValueError: Location based indexing can only have [integer, integer slice (START point is INCLUDED, END point is EXCLUDED), listlike of integers, boolean array] types
2018-11-30 10:59:44 ERROR    Traceback (most recent call last):
  File "C:\Users\McKewJ\Anaconda\envs\AirQualityToolkit\lib\site-packages\pandas\core\indexing.py", line 222, in _has_valid_tuple
    self._validate_key(k, i)
  File "C:\Users\McKewJ\Anaconda\envs\AirQualityToolkit\lib\site-packages\pandas\core\indexing.py", line 1971, in _validate_key
    "a [{types}]".format(types=self._valid_types))
ValueError: Can only index by location with a [integer, integer slice (START point is INCLUDED, END point is EXCLUDED), listlike of integers, boolean array]

During handling of the above exception, another exception occurred:

Traceback (most recent call last):
  File "u:\Git Version Control\Air-Quality-Toolkit\modules\Contemporaneous.py", line 51, in contemporaneous
    receptor_con = sorted_data.iloc[:,cols]
  File "C:\Users\McKewJ\Anaconda\envs\AirQualityToolkit\lib\site-packages\pandas\core\indexing.py", line 1472, in __getitem__
    return self._getitem_tuple(key)
  File "C:\Users\McKewJ\Anaconda\envs\AirQualityToolkit\lib\site-packages\pandas\core\indexing.py", line 2013, in _getitem_tuple
    self._has_valid_tuple(tup)
  File "C:\Users\McKewJ\Anaconda\envs\AirQualityToolkit\lib\site-packages\pandas\core\indexing.py", line 226, in _has_valid_tuple
    .format(types=self._valid_types))
ValueError: Location based indexing can only have [integer, integer slice (START point is INCLUDED, END point is EXCLUDED), listlike of integers, boolean array] types
Traceback (most recent call last):
  File "C:\Users\McKewJ\Anaconda\envs\AirQualityToolkit\lib\site-packages\pandas\core\indexing.py", line 222, in _has_valid_tuple
    self._validate_key(k, i)
  File "C:\Users\McKewJ\Anaconda\envs\AirQualityToolkit\lib\site-packages\pandas\core\indexing.py", line 1971, in _validate_key
    "a [{types}]".format(types=self._valid_types))
ValueError: Can only index by location with a [integer, integer slice (START point is INCLUDED, END point is EXCLUDED), listlike of integers, boolean array]

During handling of the above exception, another exception occurred:

Traceback (most recent call last):
  File "u:\Git Version Control\Air-Quality-Toolkit\modules\Contemporaneous.py", line 51, in contemporaneous
    receptor_con = sorted_data.iloc[:,cols]
  File "C:\Users\McKewJ\Anaconda\envs\AirQualityToolkit\lib\site-packages\pandas\core\indexing.py", line 1472, in __getitem__
    return self._getitem_tuple(key)
  File "C:\Users\McKewJ\Anaconda\envs\AirQualityToolkit\lib\site-packages\pandas\core\indexing.py", line 2013, in _getitem_tuple
    self._has_valid_tuple(tup)
  File "C:\Users\McKewJ\Anaconda\envs\AirQualityToolkit\lib\site-packages\pandas\core\indexing.py", line 226, in _has_valid_tuple
    .format(types=self._valid_types))
ValueError: Location based indexing can only have [integer, integer slice (START point is INCLUDED, END point is EXCLUDED), listlike of integers, boolean array] types
2018-11-30 11:00:23 ERROR    Traceback (most recent call last):
  File "C:\Users\McKewJ\Anaconda\envs\AirQualityToolkit\lib\site-packages\pandas\core\indexing.py", line 222, in _has_valid_tuple
    self._validate_key(k, i)
  File "C:\Users\McKewJ\Anaconda\envs\AirQualityToolkit\lib\site-packages\pandas\core\indexing.py", line 1971, in _validate_key
    "a [{types}]".format(types=self._valid_types))
ValueError: Can only index by location with a [integer, integer slice (START point is INCLUDED, END point is EXCLUDED), listlike of integers, boolean array]

During handling of the above exception, another exception occurred:

Traceback (most recent call last):
  File "u:\Git Version Control\Air-Quality-Toolkit\modules\Contemporaneous.py", line 52, in contemporaneous
    receptor_con = sorted_data.iloc[:,cols]
  File "C:\Users\McKewJ\Anaconda\envs\AirQualityToolkit\lib\site-packages\pandas\core\indexing.py", line 1472, in __getitem__
    return self._getitem_tuple(key)
  File "C:\Users\McKewJ\Anaconda\envs\AirQualityToolkit\lib\site-packages\pandas\core\indexing.py", line 2013, in _getitem_tuple
    self._has_valid_tuple(tup)
  File "C:\Users\McKewJ\Anaconda\envs\AirQualityToolkit\lib\site-packages\pandas\core\indexing.py", line 226, in _has_valid_tuple
    .format(types=self._valid_types))
ValueError: Location based indexing can only have [integer, integer slice (START point is INCLUDED, END point is EXCLUDED), listlike of integers, boolean array] types
Traceback (most recent call last):
  File "C:\Users\McKewJ\Anaconda\envs\AirQualityToolkit\lib\site-packages\pandas\core\indexing.py", line 222, in _has_valid_tuple
    self._validate_key(k, i)
  File "C:\Users\McKewJ\Anaconda\envs\AirQualityToolkit\lib\site-packages\pandas\core\indexing.py", line 1971, in _validate_key
    "a [{types}]".format(types=self._valid_types))
ValueError: Can only index by location with a [integer, integer slice (START point is INCLUDED, END point is EXCLUDED), listlike of integers, boolean array]

During handling of the above exception, another exception occurred:

Traceback (most recent call last):
  File "u:\Git Version Control\Air-Quality-Toolkit\modules\Contemporaneous.py", line 52, in contemporaneous
    receptor_con = sorted_data.iloc[:,cols]
  File "C:\Users\McKewJ\Anaconda\envs\AirQualityToolkit\lib\site-packages\pandas\core\indexing.py", line 1472, in __getitem__
    return self._getitem_tuple(key)
  File "C:\Users\McKewJ\Anaconda\envs\AirQualityToolkit\lib\site-packages\pandas\core\indexing.py", line 2013, in _getitem_tuple
    self._has_valid_tuple(tup)
  File "C:\Users\McKewJ\Anaconda\envs\AirQualityToolkit\lib\site-packages\pandas\core\indexing.py", line 226, in _has_valid_tuple
    .format(types=self._valid_types))
ValueError: Location based indexing can only have [integer, integer slice (START point is INCLUDED, END point is EXCLUDED), listlike of integers, boolean array] types
2018-11-30 11:00:23 ERROR    Traceback (most recent call last):
  File "C:\Users\McKewJ\Anaconda\envs\AirQualityToolkit\lib\site-packages\pandas\core\indexing.py", line 222, in _has_valid_tuple
    self._validate_key(k, i)
  File "C:\Users\McKewJ\Anaconda\envs\AirQualityToolkit\lib\site-packages\pandas\core\indexing.py", line 1971, in _validate_key
    "a [{types}]".format(types=self._valid_types))
ValueError: Can only index by location with a [integer, integer slice (START point is INCLUDED, END point is EXCLUDED), listlike of integers, boolean array]

During handling of the above exception, another exception occurred:

Traceback (most recent call last):
  File "u:\Git Version Control\Air-Quality-Toolkit\modules\Contemporaneous.py", line 52, in contemporaneous
    receptor_con = sorted_data.iloc[:,cols]
  File "C:\Users\McKewJ\Anaconda\envs\AirQualityToolkit\lib\site-packages\pandas\core\indexing.py", line 1472, in __getitem__
    return self._getitem_tuple(key)
  File "C:\Users\McKewJ\Anaconda\envs\AirQualityToolkit\lib\site-packages\pandas\core\indexing.py", line 2013, in _getitem_tuple
    self._has_valid_tuple(tup)
  File "C:\Users\McKewJ\Anaconda\envs\AirQualityToolkit\lib\site-packages\pandas\core\indexing.py", line 226, in _has_valid_tuple
    .format(types=self._valid_types))
ValueError: Location based indexing can only have [integer, integer slice (START point is INCLUDED, END point is EXCLUDED), listlike of integers, boolean array] types
Traceback (most recent call last):
  File "C:\Users\McKewJ\Anaconda\envs\AirQualityToolkit\lib\site-packages\pandas\core\indexing.py", line 222, in _has_valid_tuple
    self._validate_key(k, i)
  File "C:\Users\McKewJ\Anaconda\envs\AirQualityToolkit\lib\site-packages\pandas\core\indexing.py", line 1971, in _validate_key
    "a [{types}]".format(types=self._valid_types))
ValueError: Can only index by location with a [integer, integer slice (START point is INCLUDED, END point is EXCLUDED), listlike of integers, boolean array]

During handling of the above exception, another exception occurred:

Traceback (most recent call last):
  File "u:\Git Version Control\Air-Quality-Toolkit\modules\Contemporaneous.py", line 52, in contemporaneous
    receptor_con = sorted_data.iloc[:,cols]
  File "C:\Users\McKewJ\Anaconda\envs\AirQualityToolkit\lib\site-packages\pandas\core\indexing.py", line 1472, in __getitem__
    return self._getitem_tuple(key)
  File "C:\Users\McKewJ\Anaconda\envs\AirQualityToolkit\lib\site-packages\pandas\core\indexing.py", line 2013, in _getitem_tuple
    self._has_valid_tuple(tup)
  File "C:\Users\McKewJ\Anaconda\envs\AirQualityToolkit\lib\site-packages\pandas\core\indexing.py", line 226, in _has_valid_tuple
    .format(types=self._valid_types))
ValueError: Location based indexing can only have [integer, integer slice (START point is INCLUDED, END point is EXCLUDED), listlike of integers, boolean array] types
2018-11-30 11:02:46 ERROR    Traceback (most recent call last):
  File "C:\Users\McKewJ\Anaconda\envs\AirQualityToolkit\lib\site-packages\pandas\core\indexing.py", line 222, in _has_valid_tuple
    self._validate_key(k, i)
  File "C:\Users\McKewJ\Anaconda\envs\AirQualityToolkit\lib\site-packages\pandas\core\indexing.py", line 1971, in _validate_key
    "a [{types}]".format(types=self._valid_types))
ValueError: Can only index by location with a [integer, integer slice (START point is INCLUDED, END point is EXCLUDED), listlike of integers, boolean array]

During handling of the above exception, another exception occurred:

Traceback (most recent call last):
  File "u:\Git Version Control\Air-Quality-Toolkit\modules\Contemporaneous.py", line 51, in contemporaneous
    receptor_con = sorted_data.iloc[:,cols]
  File "C:\Users\McKewJ\Anaconda\envs\AirQualityToolkit\lib\site-packages\pandas\core\indexing.py", line 1472, in __getitem__
    return self._getitem_tuple(key)
  File "C:\Users\McKewJ\Anaconda\envs\AirQualityToolkit\lib\site-packages\pandas\core\indexing.py", line 2013, in _getitem_tuple
    self._has_valid_tuple(tup)
  File "C:\Users\McKewJ\Anaconda\envs\AirQualityToolkit\lib\site-packages\pandas\core\indexing.py", line 226, in _has_valid_tuple
    .format(types=self._valid_types))
ValueError: Location based indexing can only have [integer, integer slice (START point is INCLUDED, END point is EXCLUDED), listlike of integers, boolean array] types
Traceback (most recent call last):
  File "C:\Users\McKewJ\Anaconda\envs\AirQualityToolkit\lib\site-packages\pandas\core\indexing.py", line 222, in _has_valid_tuple
    self._validate_key(k, i)
  File "C:\Users\McKewJ\Anaconda\envs\AirQualityToolkit\lib\site-packages\pandas\core\indexing.py", line 1971, in _validate_key
    "a [{types}]".format(types=self._valid_types))
ValueError: Can only index by location with a [integer, integer slice (START point is INCLUDED, END point is EXCLUDED), listlike of integers, boolean array]

During handling of the above exception, another exception occurred:

Traceback (most recent call last):
  File "u:\Git Version Control\Air-Quality-Toolkit\modules\Contemporaneous.py", line 51, in contemporaneous
    receptor_con = sorted_data.iloc[:,cols]
  File "C:\Users\McKewJ\Anaconda\envs\AirQualityToolkit\lib\site-packages\pandas\core\indexing.py", line 1472, in __getitem__
    return self._getitem_tuple(key)
  File "C:\Users\McKewJ\Anaconda\envs\AirQualityToolkit\lib\site-packages\pandas\core\indexing.py", line 2013, in _getitem_tuple
    self._has_valid_tuple(tup)
  File "C:\Users\McKewJ\Anaconda\envs\AirQualityToolkit\lib\site-packages\pandas\core\indexing.py", line 226, in _has_valid_tuple
    .format(types=self._valid_types))
ValueError: Location based indexing can only have [integer, integer slice (START point is INCLUDED, END point is EXCLUDED), listlike of integers, boolean array] types
2018-11-30 11:02:46 ERROR    Traceback (most recent call last):
  File "C:\Users\McKewJ\Anaconda\envs\AirQualityToolkit\lib\site-packages\pandas\core\indexing.py", line 222, in _has_valid_tuple
    self._validate_key(k, i)
  File "C:\Users\McKewJ\Anaconda\envs\AirQualityToolkit\lib\site-packages\pandas\core\indexing.py", line 1971, in _validate_key
    "a [{types}]".format(types=self._valid_types))
ValueError: Can only index by location with a [integer, integer slice (START point is INCLUDED, END point is EXCLUDED), listlike of integers, boolean array]

During handling of the above exception, another exception occurred:

Traceback (most recent call last):
  File "u:\Git Version Control\Air-Quality-Toolkit\modules\Contemporaneous.py", line 51, in contemporaneous
    receptor_con = sorted_data.iloc[:,cols]
  File "C:\Users\McKewJ\Anaconda\envs\AirQualityToolkit\lib\site-packages\pandas\core\indexing.py", line 1472, in __getitem__
    return self._getitem_tuple(key)
  File "C:\Users\McKewJ\Anaconda\envs\AirQualityToolkit\lib\site-packages\pandas\core\indexing.py", line 2013, in _getitem_tuple
    self._has_valid_tuple(tup)
  File "C:\Users\McKewJ\Anaconda\envs\AirQualityToolkit\lib\site-packages\pandas\core\indexing.py", line 226, in _has_valid_tuple
    .format(types=self._valid_types))
ValueError: Location based indexing can only have [integer, integer slice (START point is INCLUDED, END point is EXCLUDED), listlike of integers, boolean array] types
Traceback (most recent call last):
  File "C:\Users\McKewJ\Anaconda\envs\AirQualityToolkit\lib\site-packages\pandas\core\indexing.py", line 222, in _has_valid_tuple
    self._validate_key(k, i)
  File "C:\Users\McKewJ\Anaconda\envs\AirQualityToolkit\lib\site-packages\pandas\core\indexing.py", line 1971, in _validate_key
    "a [{types}]".format(types=self._valid_types))
ValueError: Can only index by location with a [integer, integer slice (START point is INCLUDED, END point is EXCLUDED), listlike of integers, boolean array]

During handling of the above exception, another exception occurred:

Traceback (most recent call last):
  File "u:\Git Version Control\Air-Quality-Toolkit\modules\Contemporaneous.py", line 51, in contemporaneous
    receptor_con = sorted_data.iloc[:,cols]
  File "C:\Users\McKewJ\Anaconda\envs\AirQualityToolkit\lib\site-packages\pandas\core\indexing.py", line 1472, in __getitem__
    return self._getitem_tuple(key)
  File "C:\Users\McKewJ\Anaconda\envs\AirQualityToolkit\lib\site-packages\pandas\core\indexing.py", line 2013, in _getitem_tuple
    self._has_valid_tuple(tup)
  File "C:\Users\McKewJ\Anaconda\envs\AirQualityToolkit\lib\site-packages\pandas\core\indexing.py", line 226, in _has_valid_tuple
    .format(types=self._valid_types))
ValueError: Location based indexing can only have [integer, integer slice (START point is INCLUDED, END point is EXCLUDED), listlike of integers, boolean array] types
2018-11-30 11:03:45 ERROR    Traceback (most recent call last):
  File "C:\Users\McKewJ\Anaconda\envs\AirQualityToolkit\lib\site-packages\pandas\core\indexing.py", line 222, in _has_valid_tuple
    self._validate_key(k, i)
  File "C:\Users\McKewJ\Anaconda\envs\AirQualityToolkit\lib\site-packages\pandas\core\indexing.py", line 1971, in _validate_key
    "a [{types}]".format(types=self._valid_types))
ValueError: Can only index by location with a [integer, integer slice (START point is INCLUDED, END point is EXCLUDED), listlike of integers, boolean array]

During handling of the above exception, another exception occurred:

Traceback (most recent call last):
  File "u:\Git Version Control\Air-Quality-Toolkit\modules\Contemporaneous.py", line 51, in contemporaneous
    receptor_con = sorted_data.iloc[:,cols]
  File "C:\Users\McKewJ\Anaconda\envs\AirQualityToolkit\lib\site-packages\pandas\core\indexing.py", line 1472, in __getitem__
    return self._getitem_tuple(key)
  File "C:\Users\McKewJ\Anaconda\envs\AirQualityToolkit\lib\site-packages\pandas\core\indexing.py", line 2013, in _getitem_tuple
    self._has_valid_tuple(tup)
  File "C:\Users\McKewJ\Anaconda\envs\AirQualityToolkit\lib\site-packages\pandas\core\indexing.py", line 226, in _has_valid_tuple
    .format(types=self._valid_types))
ValueError: Location based indexing can only have [integer, integer slice (START point is INCLUDED, END point is EXCLUDED), listlike of integers, boolean array] types
Traceback (most recent call last):
  File "C:\Users\McKewJ\Anaconda\envs\AirQualityToolkit\lib\site-packages\pandas\core\indexing.py", line 222, in _has_valid_tuple
    self._validate_key(k, i)
  File "C:\Users\McKewJ\Anaconda\envs\AirQualityToolkit\lib\site-packages\pandas\core\indexing.py", line 1971, in _validate_key
    "a [{types}]".format(types=self._valid_types))
ValueError: Can only index by location with a [integer, integer slice (START point is INCLUDED, END point is EXCLUDED), listlike of integers, boolean array]

During handling of the above exception, another exception occurred:

Traceback (most recent call last):
  File "u:\Git Version Control\Air-Quality-Toolkit\modules\Contemporaneous.py", line 51, in contemporaneous
    receptor_con = sorted_data.iloc[:,cols]
  File "C:\Users\McKewJ\Anaconda\envs\AirQualityToolkit\lib\site-packages\pandas\core\indexing.py", line 1472, in __getitem__
    return self._getitem_tuple(key)
  File "C:\Users\McKewJ\Anaconda\envs\AirQualityToolkit\lib\site-packages\pandas\core\indexing.py", line 2013, in _getitem_tuple
    self._has_valid_tuple(tup)
  File "C:\Users\McKewJ\Anaconda\envs\AirQualityToolkit\lib\site-packages\pandas\core\indexing.py", line 226, in _has_valid_tuple
    .format(types=self._valid_types))
ValueError: Location based indexing can only have [integer, integer slice (START point is INCLUDED, END point is EXCLUDED), listlike of integers, boolean array] types
2018-11-30 11:03:45 ERROR    Traceback (most recent call last):
  File "C:\Users\McKewJ\Anaconda\envs\AirQualityToolkit\lib\site-packages\pandas\core\indexing.py", line 222, in _has_valid_tuple
    self._validate_key(k, i)
  File "C:\Users\McKewJ\Anaconda\envs\AirQualityToolkit\lib\site-packages\pandas\core\indexing.py", line 1971, in _validate_key
    "a [{types}]".format(types=self._valid_types))
ValueError: Can only index by location with a [integer, integer slice (START point is INCLUDED, END point is EXCLUDED), listlike of integers, boolean array]

During handling of the above exception, another exception occurred:

Traceback (most recent call last):
  File "u:\Git Version Control\Air-Quality-Toolkit\modules\Contemporaneous.py", line 51, in contemporaneous
    receptor_con = sorted_data.iloc[:,cols]
  File "C:\Users\McKewJ\Anaconda\envs\AirQualityToolkit\lib\site-packages\pandas\core\indexing.py", line 1472, in __getitem__
    return self._getitem_tuple(key)
  File "C:\Users\McKewJ\Anaconda\envs\AirQualityToolkit\lib\site-packages\pandas\core\indexing.py", line 2013, in _getitem_tuple
    self._has_valid_tuple(tup)
  File "C:\Users\McKewJ\Anaconda\envs\AirQualityToolkit\lib\site-packages\pandas\core\indexing.py", line 226, in _has_valid_tuple
    .format(types=self._valid_types))
ValueError: Location based indexing can only have [integer, integer slice (START point is INCLUDED, END point is EXCLUDED), listlike of integers, boolean array] types
Traceback (most recent call last):
  File "C:\Users\McKewJ\Anaconda\envs\AirQualityToolkit\lib\site-packages\pandas\core\indexing.py", line 222, in _has_valid_tuple
    self._validate_key(k, i)
  File "C:\Users\McKewJ\Anaconda\envs\AirQualityToolkit\lib\site-packages\pandas\core\indexing.py", line 1971, in _validate_key
    "a [{types}]".format(types=self._valid_types))
ValueError: Can only index by location with a [integer, integer slice (START point is INCLUDED, END point is EXCLUDED), listlike of integers, boolean array]

During handling of the above exception, another exception occurred:

Traceback (most recent call last):
  File "u:\Git Version Control\Air-Quality-Toolkit\modules\Contemporaneous.py", line 51, in contemporaneous
    receptor_con = sorted_data.iloc[:,cols]
  File "C:\Users\McKewJ\Anaconda\envs\AirQualityToolkit\lib\site-packages\pandas\core\indexing.py", line 1472, in __getitem__
    return self._getitem_tuple(key)
  File "C:\Users\McKewJ\Anaconda\envs\AirQualityToolkit\lib\site-packages\pandas\core\indexing.py", line 2013, in _getitem_tuple
    self._has_valid_tuple(tup)
  File "C:\Users\McKewJ\Anaconda\envs\AirQualityToolkit\lib\site-packages\pandas\core\indexing.py", line 226, in _has_valid_tuple
    .format(types=self._valid_types))
ValueError: Location based indexing can only have [integer, integer slice (START point is INCLUDED, END point is EXCLUDED), listlike of integers, boolean array] types
2018-11-30 11:04:16 ERROR    Traceback (most recent call last):
  File "C:\Users\McKewJ\Anaconda\envs\AirQualityToolkit\lib\site-packages\pandas\core\indexing.py", line 222, in _has_valid_tuple
    self._validate_key(k, i)
  File "C:\Users\McKewJ\Anaconda\envs\AirQualityToolkit\lib\site-packages\pandas\core\indexing.py", line 1971, in _validate_key
    "a [{types}]".format(types=self._valid_types))
ValueError: Can only index by location with a [integer, integer slice (START point is INCLUDED, END point is EXCLUDED), listlike of integers, boolean array]

During handling of the above exception, another exception occurred:

Traceback (most recent call last):
  File "u:\Git Version Control\Air-Quality-Toolkit\modules\Contemporaneous.py", line 52, in contemporaneous
    receptor_con = sorted_data.iloc[:,cols]
  File "C:\Users\McKewJ\Anaconda\envs\AirQualityToolkit\lib\site-packages\pandas\core\indexing.py", line 1472, in __getitem__
    return self._getitem_tuple(key)
  File "C:\Users\McKewJ\Anaconda\envs\AirQualityToolkit\lib\site-packages\pandas\core\indexing.py", line 2013, in _getitem_tuple
    self._has_valid_tuple(tup)
  File "C:\Users\McKewJ\Anaconda\envs\AirQualityToolkit\lib\site-packages\pandas\core\indexing.py", line 226, in _has_valid_tuple
    .format(types=self._valid_types))
ValueError: Location based indexing can only have [integer, integer slice (START point is INCLUDED, END point is EXCLUDED), listlike of integers, boolean array] types
Traceback (most recent call last):
  File "C:\Users\McKewJ\Anaconda\envs\AirQualityToolkit\lib\site-packages\pandas\core\indexing.py", line 222, in _has_valid_tuple
    self._validate_key(k, i)
  File "C:\Users\McKewJ\Anaconda\envs\AirQualityToolkit\lib\site-packages\pandas\core\indexing.py", line 1971, in _validate_key
    "a [{types}]".format(types=self._valid_types))
ValueError: Can only index by location with a [integer, integer slice (START point is INCLUDED, END point is EXCLUDED), listlike of integers, boolean array]

During handling of the above exception, another exception occurred:

Traceback (most recent call last):
  File "u:\Git Version Control\Air-Quality-Toolkit\modules\Contemporaneous.py", line 52, in contemporaneous
    receptor_con = sorted_data.iloc[:,cols]
  File "C:\Users\McKewJ\Anaconda\envs\AirQualityToolkit\lib\site-packages\pandas\core\indexing.py", line 1472, in __getitem__
    return self._getitem_tuple(key)
  File "C:\Users\McKewJ\Anaconda\envs\AirQualityToolkit\lib\site-packages\pandas\core\indexing.py", line 2013, in _getitem_tuple
    self._has_valid_tuple(tup)
  File "C:\Users\McKewJ\Anaconda\envs\AirQualityToolkit\lib\site-packages\pandas\core\indexing.py", line 226, in _has_valid_tuple
    .format(types=self._valid_types))
ValueError: Location based indexing can only have [integer, integer slice (START point is INCLUDED, END point is EXCLUDED), listlike of integers, boolean array] types
2018-11-30 11:04:16 ERROR    Traceback (most recent call last):
  File "C:\Users\McKewJ\Anaconda\envs\AirQualityToolkit\lib\site-packages\pandas\core\indexing.py", line 222, in _has_valid_tuple
    self._validate_key(k, i)
  File "C:\Users\McKewJ\Anaconda\envs\AirQualityToolkit\lib\site-packages\pandas\core\indexing.py", line 1971, in _validate_key
    "a [{types}]".format(types=self._valid_types))
ValueError: Can only index by location with a [integer, integer slice (START point is INCLUDED, END point is EXCLUDED), listlike of integers, boolean array]

During handling of the above exception, another exception occurred:

Traceback (most recent call last):
  File "u:\Git Version Control\Air-Quality-Toolkit\modules\Contemporaneous.py", line 52, in contemporaneous
    receptor_con = sorted_data.iloc[:,cols]
  File "C:\Users\McKewJ\Anaconda\envs\AirQualityToolkit\lib\site-packages\pandas\core\indexing.py", line 1472, in __getitem__
    return self._getitem_tuple(key)
  File "C:\Users\McKewJ\Anaconda\envs\AirQualityToolkit\lib\site-packages\pandas\core\indexing.py", line 2013, in _getitem_tuple
    self._has_valid_tuple(tup)
  File "C:\Users\McKewJ\Anaconda\envs\AirQualityToolkit\lib\site-packages\pandas\core\indexing.py", line 226, in _has_valid_tuple
    .format(types=self._valid_types))
ValueError: Location based indexing can only have [integer, integer slice (START point is INCLUDED, END point is EXCLUDED), listlike of integers, boolean array] types
Traceback (most recent call last):
  File "C:\Users\McKewJ\Anaconda\envs\AirQualityToolkit\lib\site-packages\pandas\core\indexing.py", line 222, in _has_valid_tuple
    self._validate_key(k, i)
  File "C:\Users\McKewJ\Anaconda\envs\AirQualityToolkit\lib\site-packages\pandas\core\indexing.py", line 1971, in _validate_key
    "a [{types}]".format(types=self._valid_types))
ValueError: Can only index by location with a [integer, integer slice (START point is INCLUDED, END point is EXCLUDED), listlike of integers, boolean array]

During handling of the above exception, another exception occurred:

Traceback (most recent call last):
  File "u:\Git Version Control\Air-Quality-Toolkit\modules\Contemporaneous.py", line 52, in contemporaneous
    receptor_con = sorted_data.iloc[:,cols]
  File "C:\Users\McKewJ\Anaconda\envs\AirQualityToolkit\lib\site-packages\pandas\core\indexing.py", line 1472, in __getitem__
    return self._getitem_tuple(key)
  File "C:\Users\McKewJ\Anaconda\envs\AirQualityToolkit\lib\site-packages\pandas\core\indexing.py", line 2013, in _getitem_tuple
    self._has_valid_tuple(tup)
  File "C:\Users\McKewJ\Anaconda\envs\AirQualityToolkit\lib\site-packages\pandas\core\indexing.py", line 226, in _has_valid_tuple
    .format(types=self._valid_types))
ValueError: Location based indexing can only have [integer, integer slice (START point is INCLUDED, END point is EXCLUDED), listlike of integers, boolean array] types
2018-11-30 11:31:11 ERROR    Traceback (most recent call last):
  File "C:\Users\McKewJ\Anaconda\envs\AirQualityToolkit\lib\site-packages\pandas\core\indexes\base.py", line 3078, in get_loc
    return self._engine.get_loc(key)
  File "pandas/_libs/index.pyx", line 140, in pandas._libs.index.IndexEngine.get_loc
  File "pandas/_libs/index.pyx", line 162, in pandas._libs.index.IndexEngine.get_loc
  File "pandas/_libs/hashtable_class_helper.pxi", line 1492, in pandas._libs.hashtable.PyObjectHashTable.get_item
  File "pandas/_libs/hashtable_class_helper.pxi", line 1500, in pandas._libs.hashtable.PyObjectHashTable.get_item
KeyError: 'background'

During handling of the above exception, another exception occurred:

Traceback (most recent call last):
  File "u:\Git Version Control\Air-Quality-Toolkit\modules\Contemporaneous.py", line 51, in contemporaneous
    receptor_con['pred_cumulative'] = receptor_con.iloc[:,0] + receptor_con['background']
  File "C:\Users\McKewJ\Anaconda\envs\AirQualityToolkit\lib\site-packages\pandas\core\frame.py", line 2688, in __getitem__
    return self._getitem_column(key)
  File "C:\Users\McKewJ\Anaconda\envs\AirQualityToolkit\lib\site-packages\pandas\core\frame.py", line 2695, in _getitem_column
    return self._get_item_cache(key)
  File "C:\Users\McKewJ\Anaconda\envs\AirQualityToolkit\lib\site-packages\pandas\core\generic.py", line 2489, in _get_item_cache
    values = self._data.get(item)
  File "C:\Users\McKewJ\Anaconda\envs\AirQualityToolkit\lib\site-packages\pandas\core\internals.py", line 4115, in get
    loc = self.items.get_loc(item)
  File "C:\Users\McKewJ\Anaconda\envs\AirQualityToolkit\lib\site-packages\pandas\core\indexes\base.py", line 3080, in get_loc
    return self._engine.get_loc(self._maybe_cast_indexer(key))
  File "pandas/_libs/index.pyx", line 140, in pandas._libs.index.IndexEngine.get_loc
  File "pandas/_libs/index.pyx", line 162, in pandas._libs.index.IndexEngine.get_loc
  File "pandas/_libs/hashtable_class_helper.pxi", line 1492, in pandas._libs.hashtable.PyObjectHashTable.get_item
  File "pandas/_libs/hashtable_class_helper.pxi", line 1500, in pandas._libs.hashtable.PyObjectHashTable.get_item
KeyError: 'background'
Traceback (most recent call last):
  File "C:\Users\McKewJ\Anaconda\envs\AirQualityToolkit\lib\site-packages\pandas\core\indexes\base.py", line 3078, in get_loc
    return self._engine.get_loc(key)
  File "pandas/_libs/index.pyx", line 140, in pandas._libs.index.IndexEngine.get_loc
  File "pandas/_libs/index.pyx", line 162, in pandas._libs.index.IndexEngine.get_loc
  File "pandas/_libs/hashtable_class_helper.pxi", line 1492, in pandas._libs.hashtable.PyObjectHashTable.get_item
  File "pandas/_libs/hashtable_class_helper.pxi", line 1500, in pandas._libs.hashtable.PyObjectHashTable.get_item
KeyError: 'background'

During handling of the above exception, another exception occurred:

Traceback (most recent call last):
  File "u:\Git Version Control\Air-Quality-Toolkit\modules\Contemporaneous.py", line 51, in contemporaneous
    receptor_con['pred_cumulative'] = receptor_con.iloc[:,0] + receptor_con['background']
  File "C:\Users\McKewJ\Anaconda\envs\AirQualityToolkit\lib\site-packages\pandas\core\frame.py", line 2688, in __getitem__
    return self._getitem_column(key)
  File "C:\Users\McKewJ\Anaconda\envs\AirQualityToolkit\lib\site-packages\pandas\core\frame.py", line 2695, in _getitem_column
    return self._get_item_cache(key)
  File "C:\Users\McKewJ\Anaconda\envs\AirQualityToolkit\lib\site-packages\pandas\core\generic.py", line 2489, in _get_item_cache
    values = self._data.get(item)
  File "C:\Users\McKewJ\Anaconda\envs\AirQualityToolkit\lib\site-packages\pandas\core\internals.py", line 4115, in get
    loc = self.items.get_loc(item)
  File "C:\Users\McKewJ\Anaconda\envs\AirQualityToolkit\lib\site-packages\pandas\core\indexes\base.py", line 3080, in get_loc
    return self._engine.get_loc(self._maybe_cast_indexer(key))
  File "pandas/_libs/index.pyx", line 140, in pandas._libs.index.IndexEngine.get_loc
  File "pandas/_libs/index.pyx", line 162, in pandas._libs.index.IndexEngine.get_loc
  File "pandas/_libs/hashtable_class_helper.pxi", line 1492, in pandas._libs.hashtable.PyObjectHashTable.get_item
  File "pandas/_libs/hashtable_class_helper.pxi", line 1500, in pandas._libs.hashtable.PyObjectHashTable.get_item
KeyError: 'background'
2018-11-30 11:31:11 ERROR    Traceback (most recent call last):
  File "C:\Users\McKewJ\Anaconda\envs\AirQualityToolkit\lib\site-packages\pandas\core\indexes\base.py", line 3078, in get_loc
    return self._engine.get_loc(key)
  File "pandas/_libs/index.pyx", line 140, in pandas._libs.index.IndexEngine.get_loc
  File "pandas/_libs/index.pyx", line 162, in pandas._libs.index.IndexEngine.get_loc
  File "pandas/_libs/hashtable_class_helper.pxi", line 1492, in pandas._libs.hashtable.PyObjectHashTable.get_item
  File "pandas/_libs/hashtable_class_helper.pxi", line 1500, in pandas._libs.hashtable.PyObjectHashTable.get_item
KeyError: 'background'

During handling of the above exception, another exception occurred:

Traceback (most recent call last):
  File "u:\Git Version Control\Air-Quality-Toolkit\modules\Contemporaneous.py", line 51, in contemporaneous
    receptor_con['pred_cumulative'] = receptor_con.iloc[:,0] + receptor_con['background']
  File "C:\Users\McKewJ\Anaconda\envs\AirQualityToolkit\lib\site-packages\pandas\core\frame.py", line 2688, in __getitem__
    return self._getitem_column(key)
  File "C:\Users\McKewJ\Anaconda\envs\AirQualityToolkit\lib\site-packages\pandas\core\frame.py", line 2695, in _getitem_column
    return self._get_item_cache(key)
  File "C:\Users\McKewJ\Anaconda\envs\AirQualityToolkit\lib\site-packages\pandas\core\generic.py", line 2489, in _get_item_cache
    values = self._data.get(item)
  File "C:\Users\McKewJ\Anaconda\envs\AirQualityToolkit\lib\site-packages\pandas\core\internals.py", line 4115, in get
    loc = self.items.get_loc(item)
  File "C:\Users\McKewJ\Anaconda\envs\AirQualityToolkit\lib\site-packages\pandas\core\indexes\base.py", line 3080, in get_loc
    return self._engine.get_loc(self._maybe_cast_indexer(key))
  File "pandas/_libs/index.pyx", line 140, in pandas._libs.index.IndexEngine.get_loc
  File "pandas/_libs/index.pyx", line 162, in pandas._libs.index.IndexEngine.get_loc
  File "pandas/_libs/hashtable_class_helper.pxi", line 1492, in pandas._libs.hashtable.PyObjectHashTable.get_item
  File "pandas/_libs/hashtable_class_helper.pxi", line 1500, in pandas._libs.hashtable.PyObjectHashTable.get_item
KeyError: 'background'
Traceback (most recent call last):
  File "C:\Users\McKewJ\Anaconda\envs\AirQualityToolkit\lib\site-packages\pandas\core\indexes\base.py", line 3078, in get_loc
    return self._engine.get_loc(key)
  File "pandas/_libs/index.pyx", line 140, in pandas._libs.index.IndexEngine.get_loc
  File "pandas/_libs/index.pyx", line 162, in pandas._libs.index.IndexEngine.get_loc
  File "pandas/_libs/hashtable_class_helper.pxi", line 1492, in pandas._libs.hashtable.PyObjectHashTable.get_item
  File "pandas/_libs/hashtable_class_helper.pxi", line 1500, in pandas._libs.hashtable.PyObjectHashTable.get_item
KeyError: 'background'

During handling of the above exception, another exception occurred:

Traceback (most recent call last):
  File "u:\Git Version Control\Air-Quality-Toolkit\modules\Contemporaneous.py", line 51, in contemporaneous
    receptor_con['pred_cumulative'] = receptor_con.iloc[:,0] + receptor_con['background']
  File "C:\Users\McKewJ\Anaconda\envs\AirQualityToolkit\lib\site-packages\pandas\core\frame.py", line 2688, in __getitem__
    return self._getitem_column(key)
  File "C:\Users\McKewJ\Anaconda\envs\AirQualityToolkit\lib\site-packages\pandas\core\frame.py", line 2695, in _getitem_column
    return self._get_item_cache(key)
  File "C:\Users\McKewJ\Anaconda\envs\AirQualityToolkit\lib\site-packages\pandas\core\generic.py", line 2489, in _get_item_cache
    values = self._data.get(item)
  File "C:\Users\McKewJ\Anaconda\envs\AirQualityToolkit\lib\site-packages\pandas\core\internals.py", line 4115, in get
    loc = self.items.get_loc(item)
  File "C:\Users\McKewJ\Anaconda\envs\AirQualityToolkit\lib\site-packages\pandas\core\indexes\base.py", line 3080, in get_loc
    return self._engine.get_loc(self._maybe_cast_indexer(key))
  File "pandas/_libs/index.pyx", line 140, in pandas._libs.index.IndexEngine.get_loc
  File "pandas/_libs/index.pyx", line 162, in pandas._libs.index.IndexEngine.get_loc
  File "pandas/_libs/hashtable_class_helper.pxi", line 1492, in pandas._libs.hashtable.PyObjectHashTable.get_item
  File "pandas/_libs/hashtable_class_helper.pxi", line 1500, in pandas._libs.hashtable.PyObjectHashTable.get_item
KeyError: 'background'
2018-11-30 11:45:39 ERROR    Traceback (most recent call last):
  File "u:\Git Version Control\Air-Quality-Toolkit\modules\Contemporaneous.py", line 68, in contemporaneous
    full_sorted = full_sorted.append(result,ignore_index=True)
  File "C:\Users\McKewJ\Anaconda\envs\AirQualityToolkit\lib\site-packages\pandas\core\frame.py", line 6211, in append
    sort=sort)
  File "C:\Users\McKewJ\Anaconda\envs\AirQualityToolkit\lib\site-packages\pandas\core\reshape\concat.py", line 226, in concat
    return op.get_result()
  File "C:\Users\McKewJ\Anaconda\envs\AirQualityToolkit\lib\site-packages\pandas\core\reshape\concat.py", line 423, in get_result
    copy=self.copy)
  File "C:\Users\McKewJ\Anaconda\envs\AirQualityToolkit\lib\site-packages\pandas\core\internals.py", line 5425, in concatenate_block_managers
    return BlockManager(blocks, axes)
  File "C:\Users\McKewJ\Anaconda\envs\AirQualityToolkit\lib\site-packages\pandas\core\internals.py", line 3282, in __init__
    self._verify_integrity()
  File "C:\Users\McKewJ\Anaconda\envs\AirQualityToolkit\lib\site-packages\pandas\core\internals.py", line 3498, in _verify_integrity
    len(self.items), tot_items))
AssertionError: Number of manager items must equal union of block items
# manager items: 9, # tot_items: 13
Traceback (most recent call last):
  File "u:\Git Version Control\Air-Quality-Toolkit\modules\Contemporaneous.py", line 68, in contemporaneous
    full_sorted = full_sorted.append(result,ignore_index=True)
  File "C:\Users\McKewJ\Anaconda\envs\AirQualityToolkit\lib\site-packages\pandas\core\frame.py", line 6211, in append
    sort=sort)
  File "C:\Users\McKewJ\Anaconda\envs\AirQualityToolkit\lib\site-packages\pandas\core\reshape\concat.py", line 226, in concat
    return op.get_result()
  File "C:\Users\McKewJ\Anaconda\envs\AirQualityToolkit\lib\site-packages\pandas\core\reshape\concat.py", line 423, in get_result
    copy=self.copy)
  File "C:\Users\McKewJ\Anaconda\envs\AirQualityToolkit\lib\site-packages\pandas\core\internals.py", line 5425, in concatenate_block_managers
    return BlockManager(blocks, axes)
  File "C:\Users\McKewJ\Anaconda\envs\AirQualityToolkit\lib\site-packages\pandas\core\internals.py", line 3282, in __init__
    self._verify_integrity()
  File "C:\Users\McKewJ\Anaconda\envs\AirQualityToolkit\lib\site-packages\pandas\core\internals.py", line 3498, in _verify_integrity
    len(self.items), tot_items))
AssertionError: Number of manager items must equal union of block items
# manager items: 9, # tot_items: 13
2018-11-30 11:45:39 ERROR    Traceback (most recent call last):
  File "u:\Git Version Control\Air-Quality-Toolkit\modules\Contemporaneous.py", line 68, in contemporaneous
    full_sorted = full_sorted.append(result,ignore_index=True)
  File "C:\Users\McKewJ\Anaconda\envs\AirQualityToolkit\lib\site-packages\pandas\core\frame.py", line 6211, in append
    sort=sort)
  File "C:\Users\McKewJ\Anaconda\envs\AirQualityToolkit\lib\site-packages\pandas\core\reshape\concat.py", line 226, in concat
    return op.get_result()
  File "C:\Users\McKewJ\Anaconda\envs\AirQualityToolkit\lib\site-packages\pandas\core\reshape\concat.py", line 423, in get_result
    copy=self.copy)
  File "C:\Users\McKewJ\Anaconda\envs\AirQualityToolkit\lib\site-packages\pandas\core\internals.py", line 5425, in concatenate_block_managers
    return BlockManager(blocks, axes)
  File "C:\Users\McKewJ\Anaconda\envs\AirQualityToolkit\lib\site-packages\pandas\core\internals.py", line 3282, in __init__
    self._verify_integrity()
  File "C:\Users\McKewJ\Anaconda\envs\AirQualityToolkit\lib\site-packages\pandas\core\internals.py", line 3498, in _verify_integrity
    len(self.items), tot_items))
AssertionError: Number of manager items must equal union of block items
# manager items: 9, # tot_items: 13
Traceback (most recent call last):
  File "u:\Git Version Control\Air-Quality-Toolkit\modules\Contemporaneous.py", line 68, in contemporaneous
    full_sorted = full_sorted.append(result,ignore_index=True)
  File "C:\Users\McKewJ\Anaconda\envs\AirQualityToolkit\lib\site-packages\pandas\core\frame.py", line 6211, in append
    sort=sort)
  File "C:\Users\McKewJ\Anaconda\envs\AirQualityToolkit\lib\site-packages\pandas\core\reshape\concat.py", line 226, in concat
    return op.get_result()
  File "C:\Users\McKewJ\Anaconda\envs\AirQualityToolkit\lib\site-packages\pandas\core\reshape\concat.py", line 423, in get_result
    copy=self.copy)
  File "C:\Users\McKewJ\Anaconda\envs\AirQualityToolkit\lib\site-packages\pandas\core\internals.py", line 5425, in concatenate_block_managers
    return BlockManager(blocks, axes)
  File "C:\Users\McKewJ\Anaconda\envs\AirQualityToolkit\lib\site-packages\pandas\core\internals.py", line 3282, in __init__
    self._verify_integrity()
  File "C:\Users\McKewJ\Anaconda\envs\AirQualityToolkit\lib\site-packages\pandas\core\internals.py", line 3498, in _verify_integrity
    len(self.items), tot_items))
AssertionError: Number of manager items must equal union of block items
# manager items: 9, # tot_items: 13
2018-11-30 11:47:07 ERROR    Traceback (most recent call last):
  File "u:\Git Version Control\Air-Quality-Toolkit\modules\Contemporaneous.py", line 68, in contemporaneous
    full_sorted = full_sorted.append(result)
  File "C:\Users\McKewJ\Anaconda\envs\AirQualityToolkit\lib\site-packages\pandas\core\frame.py", line 6211, in append
    sort=sort)
  File "C:\Users\McKewJ\Anaconda\envs\AirQualityToolkit\lib\site-packages\pandas\core\reshape\concat.py", line 226, in concat
    return op.get_result()
  File "C:\Users\McKewJ\Anaconda\envs\AirQualityToolkit\lib\site-packages\pandas\core\reshape\concat.py", line 423, in get_result
    copy=self.copy)
  File "C:\Users\McKewJ\Anaconda\envs\AirQualityToolkit\lib\site-packages\pandas\core\internals.py", line 5425, in concatenate_block_managers
    return BlockManager(blocks, axes)
  File "C:\Users\McKewJ\Anaconda\envs\AirQualityToolkit\lib\site-packages\pandas\core\internals.py", line 3282, in __init__
    self._verify_integrity()
  File "C:\Users\McKewJ\Anaconda\envs\AirQualityToolkit\lib\site-packages\pandas\core\internals.py", line 3498, in _verify_integrity
    len(self.items), tot_items))
AssertionError: Number of manager items must equal union of block items
# manager items: 9, # tot_items: 13
Traceback (most recent call last):
  File "u:\Git Version Control\Air-Quality-Toolkit\modules\Contemporaneous.py", line 68, in contemporaneous
    full_sorted = full_sorted.append(result)
  File "C:\Users\McKewJ\Anaconda\envs\AirQualityToolkit\lib\site-packages\pandas\core\frame.py", line 6211, in append
    sort=sort)
  File "C:\Users\McKewJ\Anaconda\envs\AirQualityToolkit\lib\site-packages\pandas\core\reshape\concat.py", line 226, in concat
    return op.get_result()
  File "C:\Users\McKewJ\Anaconda\envs\AirQualityToolkit\lib\site-packages\pandas\core\reshape\concat.py", line 423, in get_result
    copy=self.copy)
  File "C:\Users\McKewJ\Anaconda\envs\AirQualityToolkit\lib\site-packages\pandas\core\internals.py", line 5425, in concatenate_block_managers
    return BlockManager(blocks, axes)
  File "C:\Users\McKewJ\Anaconda\envs\AirQualityToolkit\lib\site-packages\pandas\core\internals.py", line 3282, in __init__
    self._verify_integrity()
  File "C:\Users\McKewJ\Anaconda\envs\AirQualityToolkit\lib\site-packages\pandas\core\internals.py", line 3498, in _verify_integrity
    len(self.items), tot_items))
AssertionError: Number of manager items must equal union of block items
# manager items: 9, # tot_items: 13
2018-11-30 11:47:07 ERROR    Traceback (most recent call last):
  File "u:\Git Version Control\Air-Quality-Toolkit\modules\Contemporaneous.py", line 68, in contemporaneous
    full_sorted = full_sorted.append(result)
  File "C:\Users\McKewJ\Anaconda\envs\AirQualityToolkit\lib\site-packages\pandas\core\frame.py", line 6211, in append
    sort=sort)
  File "C:\Users\McKewJ\Anaconda\envs\AirQualityToolkit\lib\site-packages\pandas\core\reshape\concat.py", line 226, in concat
    return op.get_result()
  File "C:\Users\McKewJ\Anaconda\envs\AirQualityToolkit\lib\site-packages\pandas\core\reshape\concat.py", line 423, in get_result
    copy=self.copy)
  File "C:\Users\McKewJ\Anaconda\envs\AirQualityToolkit\lib\site-packages\pandas\core\internals.py", line 5425, in concatenate_block_managers
    return BlockManager(blocks, axes)
  File "C:\Users\McKewJ\Anaconda\envs\AirQualityToolkit\lib\site-packages\pandas\core\internals.py", line 3282, in __init__
    self._verify_integrity()
  File "C:\Users\McKewJ\Anaconda\envs\AirQualityToolkit\lib\site-packages\pandas\core\internals.py", line 3498, in _verify_integrity
    len(self.items), tot_items))
AssertionError: Number of manager items must equal union of block items
# manager items: 9, # tot_items: 13
Traceback (most recent call last):
  File "u:\Git Version Control\Air-Quality-Toolkit\modules\Contemporaneous.py", line 68, in contemporaneous
    full_sorted = full_sorted.append(result)
  File "C:\Users\McKewJ\Anaconda\envs\AirQualityToolkit\lib\site-packages\pandas\core\frame.py", line 6211, in append
    sort=sort)
  File "C:\Users\McKewJ\Anaconda\envs\AirQualityToolkit\lib\site-packages\pandas\core\reshape\concat.py", line 226, in concat
    return op.get_result()
  File "C:\Users\McKewJ\Anaconda\envs\AirQualityToolkit\lib\site-packages\pandas\core\reshape\concat.py", line 423, in get_result
    copy=self.copy)
  File "C:\Users\McKewJ\Anaconda\envs\AirQualityToolkit\lib\site-packages\pandas\core\internals.py", line 5425, in concatenate_block_managers
    return BlockManager(blocks, axes)
  File "C:\Users\McKewJ\Anaconda\envs\AirQualityToolkit\lib\site-packages\pandas\core\internals.py", line 3282, in __init__
    self._verify_integrity()
  File "C:\Users\McKewJ\Anaconda\envs\AirQualityToolkit\lib\site-packages\pandas\core\internals.py", line 3498, in _verify_integrity
    len(self.items), tot_items))
AssertionError: Number of manager items must equal union of block items
# manager items: 9, # tot_items: 13
2018-11-30 11:49:06 ERROR    Traceback (most recent call last):
  File "u:\Git Version Control\Air-Quality-Toolkit\modules\Contemporaneous.py", line 68, in contemporaneous
    full_sorted = pd.concat([full_sorted,result],ignore_index=True)
  File "C:\Users\McKewJ\Anaconda\envs\AirQualityToolkit\lib\site-packages\pandas\core\reshape\concat.py", line 226, in concat
    return op.get_result()
  File "C:\Users\McKewJ\Anaconda\envs\AirQualityToolkit\lib\site-packages\pandas\core\reshape\concat.py", line 423, in get_result
    copy=self.copy)
  File "C:\Users\McKewJ\Anaconda\envs\AirQualityToolkit\lib\site-packages\pandas\core\internals.py", line 5425, in concatenate_block_managers
    return BlockManager(blocks, axes)
  File "C:\Users\McKewJ\Anaconda\envs\AirQualityToolkit\lib\site-packages\pandas\core\internals.py", line 3282, in __init__
    self._verify_integrity()
  File "C:\Users\McKewJ\Anaconda\envs\AirQualityToolkit\lib\site-packages\pandas\core\internals.py", line 3498, in _verify_integrity
    len(self.items), tot_items))
AssertionError: Number of manager items must equal union of block items
# manager items: 9, # tot_items: 13
Traceback (most recent call last):
  File "u:\Git Version Control\Air-Quality-Toolkit\modules\Contemporaneous.py", line 68, in contemporaneous
    full_sorted = pd.concat([full_sorted,result],ignore_index=True)
  File "C:\Users\McKewJ\Anaconda\envs\AirQualityToolkit\lib\site-packages\pandas\core\reshape\concat.py", line 226, in concat
    return op.get_result()
  File "C:\Users\McKewJ\Anaconda\envs\AirQualityToolkit\lib\site-packages\pandas\core\reshape\concat.py", line 423, in get_result
    copy=self.copy)
  File "C:\Users\McKewJ\Anaconda\envs\AirQualityToolkit\lib\site-packages\pandas\core\internals.py", line 5425, in concatenate_block_managers
    return BlockManager(blocks, axes)
  File "C:\Users\McKewJ\Anaconda\envs\AirQualityToolkit\lib\site-packages\pandas\core\internals.py", line 3282, in __init__
    self._verify_integrity()
  File "C:\Users\McKewJ\Anaconda\envs\AirQualityToolkit\lib\site-packages\pandas\core\internals.py", line 3498, in _verify_integrity
    len(self.items), tot_items))
AssertionError: Number of manager items must equal union of block items
# manager items: 9, # tot_items: 13
2018-11-30 11:49:06 ERROR    Traceback (most recent call last):
  File "u:\Git Version Control\Air-Quality-Toolkit\modules\Contemporaneous.py", line 68, in contemporaneous
    full_sorted = pd.concat([full_sorted,result],ignore_index=True)
  File "C:\Users\McKewJ\Anaconda\envs\AirQualityToolkit\lib\site-packages\pandas\core\reshape\concat.py", line 226, in concat
    return op.get_result()
  File "C:\Users\McKewJ\Anaconda\envs\AirQualityToolkit\lib\site-packages\pandas\core\reshape\concat.py", line 423, in get_result
    copy=self.copy)
  File "C:\Users\McKewJ\Anaconda\envs\AirQualityToolkit\lib\site-packages\pandas\core\internals.py", line 5425, in concatenate_block_managers
    return BlockManager(blocks, axes)
  File "C:\Users\McKewJ\Anaconda\envs\AirQualityToolkit\lib\site-packages\pandas\core\internals.py", line 3282, in __init__
    self._verify_integrity()
  File "C:\Users\McKewJ\Anaconda\envs\AirQualityToolkit\lib\site-packages\pandas\core\internals.py", line 3498, in _verify_integrity
    len(self.items), tot_items))
AssertionError: Number of manager items must equal union of block items
# manager items: 9, # tot_items: 13
Traceback (most recent call last):
  File "u:\Git Version Control\Air-Quality-Toolkit\modules\Contemporaneous.py", line 68, in contemporaneous
    full_sorted = pd.concat([full_sorted,result],ignore_index=True)
  File "C:\Users\McKewJ\Anaconda\envs\AirQualityToolkit\lib\site-packages\pandas\core\reshape\concat.py", line 226, in concat
    return op.get_result()
  File "C:\Users\McKewJ\Anaconda\envs\AirQualityToolkit\lib\site-packages\pandas\core\reshape\concat.py", line 423, in get_result
    copy=self.copy)
  File "C:\Users\McKewJ\Anaconda\envs\AirQualityToolkit\lib\site-packages\pandas\core\internals.py", line 5425, in concatenate_block_managers
    return BlockManager(blocks, axes)
  File "C:\Users\McKewJ\Anaconda\envs\AirQualityToolkit\lib\site-packages\pandas\core\internals.py", line 3282, in __init__
    self._verify_integrity()
  File "C:\Users\McKewJ\Anaconda\envs\AirQualityToolkit\lib\site-packages\pandas\core\internals.py", line 3498, in _verify_integrity
    len(self.items), tot_items))
AssertionError: Number of manager items must equal union of block items
# manager items: 9, # tot_items: 13
